Workbook

Sheet Inputs
A1: 3D Steering / Ackermann Calculator
A3: 좌표계: X = 차량 전방(+), Y = 차량 좌측(+), Z = 위쪽(+), 단위 = mm. 노란 셀은 입력값. 아래 좌표는 계산 검증용 예시이므로 실제 좌표로 교체.
A5: Vehicle | B5: Value | D5: Rack sweep | E5: Value
A6: Wheelbase [mm] | B6: 1300 | D6: Rack direction X | E6: 0
A7: Front track [mm] | B7: 1000 | D7: Rack direction Y | E7: 1
A8: Neutral toe - Left [deg] | B8: 0 | D8: Rack direction Z | E8: 0
A9: Neutral toe - Right [deg] | B9: 0 | D9: Sweep min [mm] | E9: -60
D10: Sweep max [mm] | E10: 60
D11: Step [mm] | E11: 1
A13: Point | B13: X [mm] | C13: Y [mm] | D13: Z [mm] | E13: Description
A14: LUO | B14: 885.481 | C14: 417.136 | D14: 325.986 | E14: Left upper arm outer ball joint
A15: LLO | B15: 897.369 | C15: 447.406 | D15: 159.113 | E15: Left lower arm outer ball joint
A16: LTO | B16: 1039.644 | C16: 479.751 | D16: 210.502 | E16: Left tie-rod outer
A17: LRI | B17: 919.873 | C17: 257.454 | D17: 182.189 | E17: Left rack / tie-rod inner at neutral
A18: RUO | B18: =B14 -> 885.481 | C18: =C14*-1 -> -417.136 | D18: =D14 -> 325.986 | E18: Right upper arm outer ball joint
A19: RLO | B19: =B15 -> 897.369 | C19: =C15*-1 -> -447.406 | D19: =D15 -> 159.113 | E19: Right lower arm outer ball joint
A20: RTO | B20: =B16 -> 1039.644 | C20: =C16*-1 -> -479.751 | D20: =D16 -> 210.502 | E20: Right tie-rod outer
A21: RRI | B21: =B17 -> 919.873 | C21: =C17*-1 -> -257.454 | D21: =D17 -> 182.189 | E21: Right rack / tie-rod inner at neutral
A23: 모델 가정: 조향 시 UCA/LCA outer 두 점이 정의하는 steering axis는 고정되고, tie-rod outer가 그 축 주위를 회전함. 랙 inner는 지정한 rack direction으로 직선 이동. 범프/롤에 따른 암 위치 변화는 포함하지 않음.

Sheet Geometry
A1: Derived geometry (do not edit) | B1: Left | C1: Right
A3: axis dx | B3: =Inputs!B14-Inputs!B15 -> -11.888 | C3: =Inputs!B18-Inputs!B19 -> -11.888
A4: axis dy | B4: =Inputs!C14-Inputs!C15 -> -30.27 | C4: =Inputs!C18-Inputs!C19 -> 30.27
A5: axis dz | B5: =Inputs!D14-Inputs!D15 -> 166.873 | C5: =Inputs!D18-Inputs!D19 -> 166.873
A6: axis norm | B6: =SQRT(B3^2+B4^2+B5^2) -> 170.01234 | C6: =SQRT(C3^2+C4^2+C5^2) -> 170.01234
A7: kx | B7: =B3/B6 -> -0.069924336 | C7: =C3/C6 -> -0.069924336
A8: ky | B8: =B4/B6 -> -0.1780459 | C8: =C4/C6 -> 0.1780459
A9: kz | B9: =B5/B6 -> 0.98153464 | C9: =C5/C6 -> 0.98153464
A11: v x = TO - LO | B11: =Inputs!B16-Inputs!B15 -> 142.275 | C11: =Inputs!B20-Inputs!B19 -> 142.275
A12: v y | B12: =Inputs!C16-Inputs!C15 -> 32.345 | C12: =Inputs!C20-Inputs!C19 -> -32.345
A13: v z | B13: =Inputs!D16-Inputs!D15 -> 51.389 | C13: =Inputs!D20-Inputs!D19 -> 51.389
A14: k·v | B14: =B7*B11+B8*B12+B9*B13 -> 34.732704 | C14: =C7*C11+C8*C12+C9*C13 -> 34.732704
A15: v_parallel x | B15: =B7*B14 -> -2.4286613 | C15: =C7*C14 -> -2.4286613
A16: v_parallel y | B16: =B8*B14 -> -6.1840155 | C16: =C8*C14 -> 6.1840155
A17: v_parallel z | B17: =B9*B14 -> 34.091352 | C17: =C9*C14 -> 34.091352
A18: v_perp x | B18: =B11-B15 -> 144.70366 | C18: =C11-C15 -> 144.70366
A19: v_perp y | B19: =B12-B16 -> 38.529016 | C19: =C12-C16 -> -38.529016
A20: v_perp z | B20: =B13-B17 -> 17.297648 | C20: =C13-C17 -> 17.297648
A21: w x = k × v | B21: =B8*B13-B9*B12 -> -40.897339 | C21: =C8*C13-C9*C12 -> 40.897339
A22: w y | B22: =B9*B11-B7*B13 -> 143.24118 | C22: =C9*C11-C7*C13 -> 143.24118
A23: w z | B23: =B7*B12-B8*B11 -> 23.069778 | C23: =C7*C12-C8*C11 -> -23.069778
A24: tie-rod neutral length | B24: =SQRT((Inputs!B16-Inputs!B17)^2+(Inputs!C16-Inputs!C17)^2+(Inputs!D16-Inputs!D17)^2) -> 254.09186 | C24: =SQRT((Inputs!B20-Inputs!B21)^2+(Inputs!C20-Inputs!C21)^2+(Inputs!D20-Inputs!D21)^2) -> 254.09186
A26: neutral toe [rad] | B26: =RADIANS(Inputs!B8) -> 0 | C26: =RADIANS(Inputs!B9) -> 0
A27: f0 x | B27: =COS(B26) -> 1 | C27: =COS(C26) -> 1
A28: f0 y | B28: =SIN(B26) -> 0 | C28: =SIN(C26) -> 0
A29: f0 z | B29: =0 -> 0 | C29: =0 -> 0
A30: k·f0 | B30: =B7*B27+B8*B28+B9*B29 -> -0.069924336 | C30: =C7*C27+C8*C28+C9*C29 -> -0.069924336
A31: k×f0 x | B31: =B8*B29-B9*B28 -> 0 | C31: =C8*C29-C9*C28 -> 0
A32: k×f0 y | B32: =B9*B27-B7*B29 -> 0.98153464 | C32: =C9*C27-C7*C29 -> 0.98153464
A33: k×f0 z | B33: =B7*B28-B8*B27 -> 0.1780459 | C33: =C7*C28-C8*C27 -> -0.1780459
A35: c0 x | B35: =Inputs!B15+B15-Inputs!B17 -> -24.932661 | C35: =Inputs!B19+C15-Inputs!B21 -> -24.932661
A36: c0 y | B36: =Inputs!C15+B16-Inputs!C17 -> 183.76798 | C36: =Inputs!C19+C16-Inputs!C21 -> -183.76798
A37: c0 z | B37: =Inputs!D15+B17-Inputs!D17 -> 11.015352 | C37: =Inputs!D19+C17-Inputs!D21 -> 11.015352
A38: A0 | B38: =2*(B35*B18+B36*B19+B37*B20) -> 7326.1837 | C38: =2*(C35*C18+C36*C19+C37*C20) -> 7326.1837
A39: B0 | B39: =2*(B35*B21+B36*B22+B37*B23) -> 55193.889 | C39: =2*(C35*C21+C36*C22+C37*C23) -> -55193.889
A40: D0 | B40: =B24^2-(B35^2+B36^2+B37^2)-(B18^2+B19^2+B20^2) -> 7326.1837 | C40: =C24^2-(C35^2+C36^2+C37^2)-(C18^2+C19^2+C20^2) -> 7326.1837
A41: M0 | B41: =SQRT(B38^2+B39^2) -> 55677.988 | C41: =SQRT(C38^2+C39^2) -> 55677.988
A42: phi0 | B42: =IF(B39>=0,ACOS(MAX(-1,MIN(1,B38/B41))),-ACOS(MAX(-1,MIN(1,B38/B41)))) -> 1.4388323 | C42: =IF(C39>=0,ACOS(MAX(-1,MIN(1,C38/C41))),-ACOS(MAX(-1,MIN(1,C38/C41)))) -> -1.4388323
A43: q0 | B43: =MAX(-1,MIN(1,B40/B41)) -> 0.13158133 | C43: =MAX(-1,MIN(1,C40/C41)) -> 0.13158133
A44: alpha0 | B44: =ACOS(B43) -> 1.4388323 | C44: =ACOS(C43) -> 1.4388323
...

Sheet Math
A1: Stroke | B1: L_Rx | C1: L_Ry | D1: L_Rz | E1: L_cx | F1: L_cy | G1: L_cz | H1: L_A | I1: L_B | J1: L_D | K1: L_M | L1: L_q | M1: L_phi | N1: L_alpha | O1: L_theta | P1: L_valid | Q1: L_yaw_deg | R1: R_Rx | S1: R_Ry | T1: R_Rz | U1: R_cx | V1: R_cy | W1: R_cz | X1: R_A | Y1: R_B | Z1: R_D | AA1: R_M | AB1: R_q | AC1: R_phi | AD1: R_alpha | AE1: R_theta | AF1: R_valid | AG1: R_yaw_deg
A2: =IF(Inputs!$E$9+0*Inputs!$E$11<=Inputs!$E$10,Inputs!$E$9+0*Inputs!$E$11,"") -> -60 | B2: =IF(NOT(ISNUMBER($A2)),"",Inputs!$B$17+$A2*Inputs!$E$6/SQRT(Inputs!$E$6^2+Inputs!$E$7^2+Inputs!$E$8^2)) -> 919.873 | C2: =IF(NOT(ISNUMBER($A2)),"",Inputs!$C$17+$A2*Inputs!$E$7/SQRT(Inputs!$E$6^2+Inputs!$E$7^2+Inputs!$E$8^2)) -> 197.454 | D2: =IF(NOT(ISNUMBER($A2)),"",Inputs!$D$17+$A2*Inputs!$E$8/SQRT(Inputs!$E$6^2+Inputs!$E$7^2+Inputs!$E$8^2)) -> 182.189 | E2: =IF(NOT(ISNUMBER($A2)),"",Inputs!$B$15+Geometry!$B$15-B2) -> -24.932661 | F2: =IF(NOT(ISNUMBER($A2)),"",Inputs!$C$15+Geometry!$B$16-C2) -> 243.76798 | G2: =IF(NOT(ISNUMBER($A2)),"",Inputs!$D$15+Geometry!$B$17-D2) -> 11.015352 | H2: =IF(NOT(ISNUMBER($A2)),"",2*(E2*Geometry!$B$18+F2*Geometry!$B$19+G2*Geometry!$B$20)) -> 11949.666 | I2: =IF(NOT(ISNUMBER($A2)),"",2*(E2*Geometry!$B$21+F2*Geometry!$B$22+G2*Geometry!$B$23)) -> 72382.831 | J2: =IF(NOT(ISNUMBER($A2)),"",Geometry!$B$24^2-(E2^2+F2^2+G2^2)-(Geometry!$B$18^2+Geometry!$B$19^2+Geometry!$B$20^2)) -> -18325.974 | K2: =IF(NOT(ISNUMBER($A2)),"",SQRT(H2^2+I2^2)) -> 73362.584 | L2: =IF(OR(NOT(ISNUMBER($A2)),K2<0.000000000001),"",MAX(-1,MIN(1,J2/K2))) -> -0.24980001 | M2: =IF(OR(NOT(ISNUMBER($A2)),K2<0.000000000001),"",IF(I2>=0,ACOS(MAX(-1,MIN(1,H2/K2))),-ACOS(MAX(-1,MIN(1,H2/K2))))) -> 1.4071823 | N2: =IF(L2="","",ACOS(L2)) -> 1.82327 | O2: =IF(M2="","",MOD(M2+Geometry!$B$47*N2+PI(),2*PI())-PI()) -> -0.41608773 | P2: =IF(NOT(ISNUMBER($A2)),"",AND(K2>=0.000000000001,ABS(J2)<=K2+0.00000001)) -> TRUE | Q2: =IF(P2=FALSE,"",IF((Geometry!$B$28*COS(O2)+Geometry!$B$32*SIN(O2)+Geometry!$B$8*Geometry!$B$30*(1-COS(O2)))>=0,1,-1)*ACOS(MAX(-1,MIN(1,(Geometry!$B$27*COS(O2)+Geometry!$B$31*SIN(O2)+Geometry!$B$7*Geometry!$B$30*(1-COS(O2)))/SQRT((Geometry!$B$27*COS(O2)+Geometry!$B$31*SIN(O2)+Geometry!$B$7*Geometry!$B$30*(1-COS(O2)))^2+(Geometry!$B$28*COS(O2)+Geometry!$B$32*SIN(O2)+Geometry!$B$8*Geometry!$B$30*(1-COS(O2)))^2))))*180/PI()) -> -23.38221 | R2: =IF(NOT(ISNUMBER($A2)),"",Inputs!$B$21+$A2*Inputs!$E$6/SQRT(Inputs!$E$6^2+Inputs!$E$7^2+Inputs!$E$8^2)) -> 919.873 | S2: =IF(NOT(ISNUMBER($A2)),"",Inputs!$C$21+$A2*Inputs!$E$7/SQRT(Inputs!$E$6^2+Inputs!$E$7^2+Inputs!$E$8^2)) -> -317.454 | T2: =IF(NOT(ISNUMBER($A2)),"",Inputs!$D$21+$A2*Inputs!$E$8/SQRT(Inputs!$E$6^2+Inputs!$E$7^2+Inputs!$E$8^2)) -> 182.189 | U2: =IF(NOT(ISNUMBER($A2)),"",Inputs!$B$19+Geometry!$C$15-R2) -> -24.932661 | V2: =IF(NOT(ISNUMBER($A2)),"",Inputs!$C$19+Geometry!$C$16-S2) -> -123.76798 | W2: =IF(NOT(ISNUMBER($A2)),"",Inputs!$D$19+Geometry!$C$17-T2) -> 11.015352 | X2: =IF(NOT(ISNUMBER($A2)),"",2*(U2*Geometry!$C$18+V2*Geometry!$C$19+W2*Geometry!$C$20)) -> 2702.7018 | Y2: =IF(NOT(ISNUMBER($A2)),"",2*(U2*Geometry!$C$21+V2*Geometry!$C$22+W2*Geometry!$C$23)) -> -38004.947 | Z2: =IF(NOT(ISNUMBER($A2)),"",Geometry!$C$24^2-(U2^2+V2^2+W2^2)-(Geometry!$C$18^2+Geometry!$C$19^2+Geometry!$C$20^2)) -> 25778.342 | AA2: =IF(NOT(ISNUMBER($A2)),"",SQRT(X2^2+Y2^2)) -> 38100.927 | AB2: =IF(OR(NOT(ISNUMBER($A2)),AA2<0.000000000001),"",MAX(-1,MIN(1,Z2/AA2))) -> 0.67658044 | AC2: =IF(OR(NOT(ISNUMBER($A2)),AA2<0.000000000001),"",IF(Y2>=0,ACOS(MAX(-1,MIN(1,X2/AA2))),-ACOS(MAX(-1,MIN(1,X2/AA2))))) -> -1.4998014 | AD2: =IF(AB2="","",ACOS(AB2)) -> 0.82768747 | AE2: =IF(AC2="","",MOD(AC2+Geometry!$C$47*AD2+PI(),2*PI())-PI()) -> -0.6721139 | AF2: =IF(NOT(ISNUMBER($A2)),"",AND(AA2>=0.000000000001,ABS(Z2)<=AA2+0.00000001)) -> TRUE | AG2: =IF(AF2=FALSE,"",IF((Geometry!$C$28*COS(AE2)+Geometry!$C$32*SIN(AE2)+Geometry!$C$8*Geometry!$C$30*(1-COS(AE2)))>=0,1,-1)*ACOS(MAX(-1,MIN(1,(Geometry!$C$27*COS(AE2)+Geometry!$C$31*SIN(AE2)+Geometry!$C$7*Geometry!$C$30*(1-COS(AE2)))/SQRT((Geometry!$C$27*COS(AE2)+Geometry!$C$31*SIN(AE2)+Geometry!$C$7*Geometry!$C$30*(1-COS(AE2)))^2+(Geometry!$C$28*COS(AE2)+Geometry!$C$32*SIN(AE2)+Geometry!$C$8*Geometry!$C$30*(1-COS(AE2)))^2))))*180/PI()) -> -38.075272
A3: =IF(Inputs!$E$9+1*Inputs!$E$11<=Inputs!$E$10,Inputs!$E$9+1*Inputs!$E$11,"") -> -59 | B3: =IF(NOT(ISNUMBER($A3)),"",Inputs!$B$17+$A3*Inputs!$E$6/SQRT(Inputs!$E$6^2+Inputs!$E$7^2+Inputs!$E$8^2)) -> 919.873 | C3: =IF(NOT(ISNUMBER($A3)),"",Inputs!$C$17+$A3*Inputs!$E$7/SQRT(Inputs!$E$6^2+Inputs!$E$7^2+Inputs!$E$8^2)) -> 198.454 | D3: =IF(NOT(ISNUMBER($A3)),"",Inputs!$D$17+$A3*Inputs!$E$8/SQRT(Inputs!$E$6^2+Inputs!$E$7^2+Inputs!$E$8^2)) -> 182.189 | E3: =IF(NOT(ISNUMBER($A3)),"",Inputs!$B$15+Geometry!$B$15-B3) -> -24.932661 | F3: =IF(NOT(ISNUMBER($A3)),"",Inputs!$C$15+Geometry!$B$16-C3) -> 242.76798 | G3: =IF(NOT(ISNUMBER($A3)),"",Inputs!$D$15+Geometry!$B$17-D3) -> 11.015352 | H3: =IF(NOT(ISNUMBER($A3)),"",2*(E3*Geometry!$B$18+F3*Geometry!$B$19+G3*Geometry!$B$20)) -> 11872.608 | I3: =IF(NOT(ISNUMBER($A3)),"",2*(E3*Geometry!$B$21+F3*Geometry!$B$22+G3*Geometry!$B$23)) -> 72096.349 | J3: =IF(NOT(ISNUMBER($A3)),"",Geometry!$B$24^2-(E3^2+F3^2+G3^2)-(Geometry!$B$18^2+Geometry!$B$19^2+Geometry!$B$20^2)) -> -17839.438 | K3: =IF(NOT(ISNUMBER($A3)),"",SQRT(H3^2+I3^2)) -> 73067.382 | L3: =IF(OR(NOT(ISNUMBER($A3)),K3<0.000000000001),"",MAX(-1,MIN(1,J3/K3))) -> -0.24415051 | M3: =IF(OR(NOT(ISNUMBER($A3)),K3<0.000000000001),"",IF(I3>=0,ACOS(MAX(-1,MIN(1,H3/K3))),-ACOS(MAX(-1,MIN(1,H3/K3))))) -> 1.4075842 | N3: =IF(L3="","",ACOS(L3)) -> 1.8174399 | O3: =IF(M3="","",MOD(M3+Geometry!$B$47*N3+PI(),2*PI())-PI()) -> -0.40985572 | P3: =IF(NOT(ISNUMBER($A3)),"",AND(K3>=0.000000000001,ABS(J3)<=K3+0.00000001)) -> TRUE | Q3: =IF(P3=FALSE,"",IF((Geometry!$B$28*COS(O3)+Geometry!$B$32*SIN(O3)+Geometry!$B$8*Geometry!$B$30*(1-COS(O3)))>=0,1,-1)*ACOS(MAX(-1,MIN(1,(Geometry!$B$27*COS(O3)+Geometry!$B$31*SIN(O3)+Geometry!$B$7*Geometry!$B$30*(1-COS(O3)))/SQRT((Geometry!$B$27*COS(O3)+Geometry!$B$31*SIN(O3)+Geometry!$B$7*Geometry!$B$30*(1-COS(O3)))^2+(Geometry!$B$28*COS(O3)+Geometry!$B$32*SIN(O3)+Geometry!$B$8*Geometry!$B$30*(1-COS(O3)))^2))))*180/PI()) -> -23.031573 | R3: =IF(NOT(ISNUMBER($A3)),"",Inputs!$B$21+$A3*Inputs!$E$6/SQRT(Inputs!$E$6^2+Inputs!$E$7^2+Inputs!$E$8^2)) -> 919.873 | S3: =IF(NOT(ISNUMBER($A3)),"",Inputs!$C$21+$A3*Inputs!$E$7/SQRT(Inputs!$E$6^2+Inputs!$E$7^2+Inputs!$E$8^2)) -> -316.454 | T3: =IF(NOT(ISNUMBER($A3)),"",Inputs!$D$21+$A3*Inputs!$E$8/SQRT(Inputs!$E$6^2+Inputs!$E$7^2+Inputs!$E$8^2)) -> 182.189 | U3: =IF(NOT(ISNUMBER($A3)),"",Inputs!$B$19+Geometry!$C$15-R3) -> -24.932661 | V3: =IF(NOT(ISNUMBER($A3)),"",Inputs!$C$19+Geometry!$C$16-S3) -> -124.76798 | W3: =IF(NOT(ISNUMBER($A3)),"",Inputs!$D$19+Geometry!$C$17-T3) -> 11.015352 | X3: =IF(NOT(ISNUMBER($A3)),"",2*(U3*Geometry!$C$18+V3*Geometry!$C$19+W3*Geometry!$C$20)) -> 2779.7598 | Y3: =IF(NOT(ISNUMBER($A3)),"",2*(U3*Geometry!$C$21+V3*Geometry!$C$22+W3*Geometry!$C$23)) -> -38291.43 | Z3: =IF(NOT(ISNUMBER($A3)),"",Geometry!$C$24^2-(U3^2+V3^2+W3^2)-(Geometry!$C$18^2+Geometry!$C$19^2+Geometry!$C$20^2)) -> 25529.806 | AA3: =IF(NOT(ISNUMBER($A3)),"",SQRT(X3^2+Y3^2)) -> 38392.195 | AB3: =IF(OR(NOT(ISNUMBER($A3)),AA3<0.000000000001),"",MAX(-1,MIN(1,Z3/AA3))) -> 0.66497385 | AC3: =IF(OR(NOT(ISNUMBER($A3)),AA3<0.000000000001),"",IF(Y3>=0,ACOS(MAX(-1,MIN(1,X3/AA3))),-ACOS(MAX(-1,MIN(1,X3/AA3))))) -> -1.4983286 | AD3: =IF(AB3="","",ACOS(AB3)) -> 0.84333752 | AE3: =IF(AC3="","",MOD(AC3+Geometry!$C$47*AD3+PI(),2*PI())-PI()) -> -0.6549911 | AF3: =IF(NOT(ISNUMBER($A3)),"",AND(AA3>=0.000000000001,ABS(Z3)<=AA3+0.00000001)) -> TRUE | AG3: =IF(AF3=FALSE,"",IF((Geometry!$C$28*COS(AE3)+Geometry!$C$32*SIN(AE3)+Geometry!$C$8*Geometry!$C$30*(1-COS(AE3)))>=0,1,-1)*ACOS(MAX(-1,MIN(1,(Geometry!$C$27*COS(AE3)+Geometry!$C$31*SIN(AE3)+Geometry!$C$7*Geometry!$C$30*(1-COS(AE3)))/SQRT((Geometry!$C$27*COS(AE3)+Geometry!$C$31*SIN(AE3)+Geometry!$C$7*Geometry!$C$30*(1-COS(AE3)))^2+(Geometry!$C$28*COS(AE3)+Geometry!$C$32*SIN(AE3)+Geometry!$C$8*Geometry!$C$30*(1-COS(AE3)))^2))))*180/PI()) -> -37.096952
A4: =IF(Inputs!$E$9+2*Inputs!$E$11<=Inputs!$E$10,Inputs!$E$9+2*Inputs!$E$11,"") -> -58 | B4: =IF(NOT(ISNUMBER($A4)),"",Inputs!$B$17+$A4*Inputs!$E$6/SQRT(Inputs!$E$6^2+Inputs!$E$7^2+Inputs!$E$8^2)) -> 919.873 | C4: =IF(NOT(ISNUMBER($A4)),"",Inputs!$C$17+$A4*Inputs!$E$7/SQRT(Inputs!$E$6^2+Inputs!$E$7^2+Inputs!$E$8^2)) -> 199.454 | D4: =IF(NOT(ISNUMBER($A4)),"",Inputs!$D$17+$A4*Inputs!$E$8/SQRT(Inputs!$E$6^2+Inputs!$E$7^2+Inputs!$E$8^2)) -> 182.189 | E4: =IF(NOT(ISNUMBER($A4)),"",Inputs!$B$15+Geometry!$B$15-B4) -> -24.932661 | F4: =IF(NOT(ISNUMBER($A4)),"",Inputs!$C$15+Geometry!$B$16-C4) -> 241.76798 | G4: =IF(NOT(ISNUMBER($A4)),"",Inputs!$D$15+Geometry!$B$17-D4) -> 11.015352 | H4: =IF(NOT(ISNUMBER($A4)),"",2*(E4*Geometry!$B$18+F4*Geometry!$B$19+G4*Geometry!$B$20)) -> 11795.549 | I4: =IF(NOT(ISNUMBER($A4)),"",2*(E4*Geometry!$B$21+F4*Geometry!$B$22+G4*Geometry!$B$23)) -> 71809.866 | J4: =IF(NOT(ISNUMBER($A4)),"",Geometry!$B$24^2-(E4^2+F4^2+G4^2)-(Geometry!$B$18^2+Geometry!$B$19^2+Geometry!$B$20^2)) -> -17354.903 | K4: =IF(NOT(ISNUMBER($A4)),"",SQRT(H4^2+I4^2)) -> 72772.192 | L4: =IF(OR(NOT(ISNUMBER($A4)),K4<0.000000000001),"",MAX(-1,MIN(1,J4/K4))) -> -0.23848261 | M4: =IF(OR(NOT(ISNUMBER($A4)),K4<0.000000000001),"",IF(I4>=0,ACOS(MAX(-1,MIN(1,H4/K4))),-ACOS(MAX(-1,MIN(1,H4/K4))))) -> 1.4079894 | N4: =IF(L4="","",ACOS(L4)) -> 1.8115994 | O4: =IF(M4="","",MOD(M4+Geometry!$B$47*N4+PI(),2*PI())-PI()) -> -0.40361005 | P4: =IF(NOT(ISNUMBER($A4)),"",AND(K4>=0.000000000001,ABS(J4)<=K4+0.00000001)) -> TRUE | Q4: =IF(P4=FALSE,"",IF((Geometry!$B$28*COS(O4)+Geometry!$B$32*SIN(O4)+Geometry!$B$8*Geometry!$B$30*(1-COS(O4)))>=0,1,-1)*ACOS(MAX(-1,MIN(1,(Geometry!$B$27*COS(O4)+Geometry!$B$31*SIN(O4)+Geometry!$B$7*Geometry!$B$30*(1-COS(O4)))/SQRT((Geometry!$B$27*COS(O4)+Geometry!$B$31*SIN(O4)+Geometry!$B$7*Geometry!$B$30*(1-COS(O4)))^2+(Geometry!$B$28*COS(O4)+Geometry!$B$32*SIN(O4)+Geometry!$B$8*Geometry!$B$30*(1-COS(O4)))^2))))*180/PI()) -> -22.680202 | R4: =IF(NOT(ISNUMBER($A4)),"",Inputs!$B$21+$A4*Inputs!$E$6/SQRT(Inputs!$E$6^2+Inputs!$E$7^2+Inputs!$E$8^2)) -> 919.873 | S4: =IF(NOT(ISNUMBER($A4)),"",Inputs!$C$21+$A4*Inputs!$E$7/SQRT(Inputs!$E$6^2+Inputs!$E$7^2+Inputs!$E$8^2)) -> -315.454 | T4: =IF(NOT(ISNUMBER($A4)),"",Inputs!$D$21+$A4*Inputs!$E$8/SQRT(Inputs!$E$6^2+Inputs!$E$7^2+Inputs!$E$8^2)) -> 182.189 | U4: =IF(NOT(ISNUMBER($A4)),"",Inputs!$B$19+Geometry!$C$15-R4) -> -24.932661 | V4: =IF(NOT(ISNUMBER($A4)),"",Inputs!$C$19+Geometry!$C$16-S4) -> -125.76798 | W4: =IF(NOT(ISNUMBER($A4)),"",Inputs!$D$19+Geometry!$C$17-T4) -> 11.015352 | X4: =IF(NOT(ISNUMBER($A4)),"",2*(U4*Geometry!$C$18+V4*Geometry!$C$19+W4*Geometry!$C$20)) -> 2856.8179 | Y4: =IF(NOT(ISNUMBER($A4)),"",2*(U4*Geometry!$C$21+V4*Geometry!$C$22+W4*Geometry!$C$23)) -> -38577.912 | Z4: =IF(NOT(ISNUMBER($A4)),"",Geometry!$C$24^2-(U4^2+V4^2+W4^2)-(Geometry!$C$18^2+Geometry!$C$19^2+Geometry!$C$20^2)) -> 25279.27 | AA4: =IF(NOT(ISNUMBER($A4)),"",SQRT(X4^2+Y4^2)) -> 38683.546 | AB4: =IF(OR(NOT(ISNUMBER($A4)),AA4<0.000000000001),"",MAX(-1,MIN(1,Z4/AA4))) -> 0.65348896 | AC4: =IF(OR(NOT(ISNUMBER($A4)),AA4<0.000000000001),"",IF(Y4>=0,ACOS(MAX(-1,MIN(1,X4/AA4))),-ACOS(MAX(-1,MIN(1,X4/AA4))))) -> -1.496878 | AD4: =IF(AB4="","",ACOS(AB4)) -> 0.85861169 | AE4: =IF(AC4="","",MOD(AC4+Geometry!$C$47*AD4+PI(),2*PI())-PI()) -> -0.63826635 | AF4: =IF(NOT(ISNUMBER($A4)),"",AND(AA4>=0.000000000001,ABS(Z4)<=AA4+0.00000001)) -> TRUE | AG4: =IF(AF4=FALSE,"",IF((Geometry!$C$28*COS(AE4)+Geometry!$C$32*SIN(AE4)+Geometry!$C$8*Geometry!$C$30*(1-COS(AE4)))>=0,1,-1)*ACOS(MAX(-1,MIN(1,(Geometry!$C$27*COS(AE4)+Geometry!$C$31*SIN(AE4)+Geometry!$C$7*Geometry!$C$30*(1-COS(AE4)))/SQRT((Geometry!$C$27*COS(AE4)+Geometry!$C$31*SIN(AE4)+Geometry!$C$7*Geometry!$C$30*(1-COS(AE4)))^2+(Geometry!$C$28*COS(AE4)+Geometry!$C$32*SIN(AE4)+Geometry!$C$8*Geometry!$C$30*(1-COS(AE4)))^2))))*180/PI()) -> -36.141795
A5: =IF(Inputs!$E$9+3*Inputs!$E$11<=Inputs!$E$10,Inputs!$E$9+3*Inputs!$E$11,"") -> -57 | B5: =IF(NOT(ISNUMBER($A5)),"",Inputs!$B$17+$A5*Inputs!$E$6/SQRT(Inputs!$E$6^2+Inputs!$E$7^2+Inputs!$E$8^2)) -> 919.873 | C5: =IF(NOT(ISNUMBER($A5)),"",Inputs!$C$17+$A5*Inputs!$E$7/SQRT(Inputs!$E$6^2+Inputs!$E$7^2+Inputs!$E$8^2)) -> 200.454 | D5: =IF(NOT(ISNUMBER($A5)),"",Inputs!$D$17+$A5*Inputs!$E$8/SQRT(Inputs!$E$6^2+Inputs!$E$7^2+Inputs!$E$8^2)) -> 182.189 | E5: =IF(NOT(ISNUMBER($A5)),"",Inputs!$B$15+Geometry!$B$15-B5) -> -24.932661 | F5: =IF(NOT(ISNUMBER($A5)),"",Inputs!$C$15+Geometry!$B$16-C5) -> 240.76798 | G5: =IF(NOT(ISNUMBER($A5)),"",Inputs!$D$15+Geometry!$B$17-D5) -> 11.015352 | H5: =IF(NOT(ISNUMBER($A5)),"",2*(E5*Geometry!$B$18+F5*Geometry!$B$19+G5*Geometry!$B$20)) -> 11718.491 | I5: =IF(NOT(ISNUMBER($A5)),"",2*(E5*Geometry!$B$21+F5*Geometry!$B$22+G5*Geometry!$B$23)) -> 71523.384 | J5: =IF(NOT(ISNUMBER($A5)),"",Geometry!$B$24^2-(E5^2+F5^2+G5^2)-(Geometry!$B$18^2+Geometry!$B$19^2+Geometry!$B$20^2)) -> -16872.367 | K5: =IF(NOT(ISNUMBER($A5)),"",SQRT(H5^2+I5^2)) -> 72477.014 | L5: =IF(OR(NOT(ISNUMBER($A5)),K5<0.000000000001),"",MAX(-1,MIN(1,J5/K5))) -> -0.23279611 | M5: =IF(OR(NOT(ISNUMBER($A5)),K5<0.000000000001),"",IF(I5>=0,ACOS(MAX(-1,MIN(1,H5/K5))),-ACOS(MAX(-1,MIN(1,H5/K5))))) -> 1.4083978 | N5: =IF(L5="","",ACOS(L5)) -> 1.8057481 | O5: =IF(M5="","",MOD(M5+Geometry!$B$47*N5+PI(),2*PI())-PI()) -> -0.39735031 | P5: =IF(NOT(ISNUMBER($A5)),"",AND(K5>=0.000000000001,ABS(J5)<=K5+0.00000001)) -> TRUE | Q5: =IF(P5=FALSE,"",IF((Geometry!$B$28*COS(O5)+Geometry!$B$32*SIN(O5)+Geometry!$B$8*Geometry!$B$30*(1-COS(O5)))>=0,1,-1)*ACOS(MAX(-1,MIN(1,(Geometry!$B$27*COS(O5)+Geometry!$B$31*SIN(O5)+Geometry!$B$7*Geometry!$B$30*(1-COS(O5)))/SQRT((Geometry!$B$27*COS(O5)+Geometry!$B$31*SIN(O5)+Geometry!$B$7*Geometry!$B$30*(1-COS(O5)))^2+(Geometry!$B$28*COS(O5)+Geometry!$B$32*SIN(O5)+Geometry!$B$8*Geometry!$B$30*(1-COS(O5)))^2))))*180/PI()) -> -22.328072 | R5: =IF(NOT(ISNUMBER($A5)),"",Inputs!$B$21+$A5*Inputs!$E$6/SQRT(Inputs!$E$6^2+Inputs!$E$7^2+Inputs!$E$8^2)) -> 919.873 | S5: =IF(NOT(ISNUMBER($A5)),"",Inputs!$C$21+$A5*Inputs!$E$7/SQRT(Inputs!$E$6^2+Inputs!$E$7^2+Inputs!$E$8^2)) -> -314.454 | T5: =IF(NOT(ISNUMBER($A5)),"",Inputs!$D$21+$A5*Inputs!$E$8/SQRT(Inputs!$E$6^2+Inputs!$E$7^2+Inputs!$E$8^2)) -> 182.189 | U5: =IF(NOT(ISNUMBER($A5)),"",Inputs!$B$19+Geometry!$C$15-R5) -> -24.932661 | V5: =IF(NOT(ISNUMBER($A5)),"",Inputs!$C$19+Geometry!$C$16-S5) -> -126.76798 | W5: =IF(NOT(ISNUMBER($A5)),"",Inputs!$D$19+Geometry!$C$17-T5) -> 11.015352 | X5: =IF(NOT(ISNUMBER($A5)),"",2*(U5*Geometry!$C$18+V5*Geometry!$C$19+W5*Geometry!$C$20)) -> 2933.8759 | Y5: =IF(NOT(ISNUMBER($A5)),"",2*(U5*Geometry!$C$21+V5*Geometry!$C$22+W5*Geometry!$C$23)) -> -38864.394 | Z5: =IF(NOT(ISNUMBER($A5)),"",Geometry!$C$24^2-(U5^2+V5^2+W5^2)-(Geometry!$C$18^2+Geometry!$C$19^2+Geometry!$C$20^2)) -> 25026.734 | AA5: =IF(NOT(ISNUMBER($A5)),"",SQRT(X5^2+Y5^2)) -> 38974.976 | AB5: =IF(OR(NOT(ISNUMBER($A5)),AA5<0.000000000001),"",MAX(-1,MIN(1,Z5/AA5))) -> 0.64212313 | AC5: =IF(OR(NOT(ISNUMBER($A5)),AA5<0.000000000001),"",IF(Y5>=0,ACOS(MAX(-1,MIN(1,X5/AA5))),-ACOS(MAX(-1,MIN(1,X5/AA5))))) -> -1.4954492 | AD5: =IF(AB5="","",ACOS(AB5)) -> 0.87353172 | AE5: =IF(AC5="","",MOD(AC5+Geometry!$C$47*AD5+PI(),2*PI())-PI()) -> -0.62191744 | AF5: =IF(NOT(ISNUMBER($A5)),"",AND(AA5>=0.000000000001,ABS(Z5)<=AA5+0.00000001)) -> TRUE | AG5: =IF(AF5=FALSE,"",IF((Geometry!$C$28*COS(AE5)+Geometry!$C$32*SIN(AE5)+Geometry!$C$8*Geometry!$C$30*(1-COS(AE5)))>=0,1,-1)*ACOS(MAX(-1,MIN(1,(Geometry!$C$27*COS(AE5)+Geometry!$C$31*SIN(AE5)+Geometry!$C$7*Geometry!$C$30*(1-COS(AE5)))/SQRT((Geometry!$C$27*COS(AE5)+Geometry!$C$31*SIN(AE5)+Geometry!$C$7*Geometry!$C$30*(1-COS(AE5)))^2+(Geometry!$C$28*COS(AE5)+Geometry!$C$32*SIN(AE5)+Geometry!$C$8*Geometry!$C$30*(1-COS(AE5)))^2))))*180/PI()) -> -35.208508
A6: =IF(Inputs!$E$9+4*Inputs!$E$11<=Inputs!$E$10,Inputs!$E$9+4*Inputs!$E$11,"") -> -56 | B6: =IF(NOT(ISNUMBER($A6)),"",Inputs!$B$17+$A6*Inputs!$E$6/SQRT(Inputs!$E$6^2+Inputs!$E$7^2+Inputs!$E$8^2)) -> 919.873 | C6: =IF(NOT(ISNUMBER($A6)),"",Inputs!$C$17+$A6*Inputs!$E$7/SQRT(Inputs!$E$6^2+Inputs!$E$7^2+Inputs!$E$8^2)) -> 201.454 | D6: =IF(NOT(ISNUMBER($A6)),"",Inputs!$D$17+$A6*Inputs!$E$8/SQRT(Inputs!$E$6^2+Inputs!$E$7^2+Inputs!$E$8^2)) -> 182.189 | E6: =IF(NOT(ISNUMBER($A6)),"",Inputs!$B$15+Geometry!$B$15-B6) -> -24.932661 | F6: =IF(NOT(ISNUMBER($A6)),"",Inputs!$C$15+Geometry!$B$16-C6) -> 239.76798 | G6: =IF(NOT(ISNUMBER($A6)),"",Inputs!$D$15+Geometry!$B$17-D6) -> 11.015352 | H6: =IF(NOT(ISNUMBER($A6)),"",2*(E6*Geometry!$B$18+F6*Geometry!$B$19+G6*Geometry!$B$20)) -> 11641.433 | I6: =IF(NOT(ISNUMBER($A6)),"",2*(E6*Geometry!$B$21+F6*Geometry!$B$22+G6*Geometry!$B$23)) -> 71236.902 | J6: =IF(NOT(ISNUMBER($A6)),"",Geometry!$B$24^2-(E6^2+F6^2+G6^2)-(Geometry!$B$18^2+Geometry!$B$19^2+Geometry!$B$20^2)) -> -16391.831 | K6: =IF(NOT(ISNUMBER($A6)),"",SQRT(H6^2+I6^2)) -> 72181.848 | L6: =IF(OR(NOT(ISNUMBER($A6)),K6<0.000000000001),"",MAX(-1,MIN(1,J6/K6))) -> -0.22709076 | M6: =IF(OR(NOT(ISNUMBER($A6)),K6<0.000000000001),"",IF(I6>=0,ACOS(MAX(-1,MIN(1,H6/K6))),-ACOS(MAX(-1,MIN(1,H6/K6))))) -> 1.4088096 | N6: =IF(L6="","",ACOS(L6)) -> 1.7998857 | O6: =IF(M6="","",MOD(M6+Geometry!$B$47*N6+PI(),2*PI())-PI()) -> -0.39107607 | P6: =IF(NOT(ISNUMBER($A6)),"",AND(K6>=0.000000000001,ABS(J6)<=K6+0.00000001)) -> TRUE | Q6: =IF(P6=FALSE,"",IF((Geometry!$B$28*COS(O6)+Geometry!$B$32*SIN(O6)+Geometry!$B$8*Geometry!$B$30*(1-COS(O6)))>=0,1,-1)*ACOS(MAX(-1,MIN(1,(Geometry!$B$27*COS(O6)+Geometry!$B$31*SIN(O6)+Geometry!$B$7*Geometry!$B$30*(1-COS(O6)))/SQRT((Geometry!$B$27*COS(O6)+Geometry!$B$31*SIN(O6)+Geometry!$B$7*Geometry!$B$30*(1-COS(O6)))^2+(Geometry!$B$28*COS(O6)+Geometry!$B$32*SIN(O6)+Geometry!$B$8*Geometry!$B$30*(1-COS(O6)))^2))))*180/PI()) -> -21.97516 | R6: =IF(NOT(ISNUMBER($A6)),"",Inputs!$B$21+$A6*Inputs!$E$6/SQRT(Inputs!$E$6^2+Inputs!$E$7^2+Inputs!$E$8^2)) -> 919.873 | S6: =IF(NOT(ISNUMBER($A6)),"",Inputs!$C$21+$A6*Inputs!$E$7/SQRT(Inputs!$E$6^2+Inputs!$E$7^2+Inputs!$E$8^2)) -> -313.454 | T6: =IF(NOT(ISNUMBER($A6)),"",Inputs!$D$21+$A6*Inputs!$E$8/SQRT(Inputs!$E$6^2+Inputs!$E$7^2+Inputs!$E$8^2)) -> 182.189 | U6: =IF(NOT(ISNUMBER($A6)),"",Inputs!$B$19+Geometry!$C$15-R6) -> -24.932661 | V6: =IF(NOT(ISNUMBER($A6)),"",Inputs!$C$19+Geometry!$C$16-S6) -> -127.76798 | W6: =IF(NOT(ISNUMBER($A6)),"",Inputs!$D$19+Geometry!$C$17-T6) -> 11.015352 | X6: =IF(NOT(ISNUMBER($A6)),"",2*(U6*Geometry!$C$18+V6*Geometry!$C$19+W6*Geometry!$C$20)) -> 3010.9339 | Y6: =IF(NOT(ISNUMBER($A6)),"",2*(U6*Geometry!$C$21+V6*Geometry!$C$22+W6*Geometry!$C$23)) -> -39150.877 | Z6: =IF(NOT(ISNUMBER($A6)),"",Geometry!$C$24^2-(U6^2+V6^2+W6^2)-(Geometry!$C$18^2+Geometry!$C$19^2+Geometry!$C$20^2)) -> 24772.198 | AA6: =IF(NOT(ISNUMBER($A6)),"",SQRT(X6^2+Y6^2)) -> 39266.485 | AB6: =IF(OR(NOT(ISNUMBER($A6)),AA6<0.000000000001),"",MAX(-1,MIN(1,Z6/AA6))) -> 0.63087383 | AC6: =IF(OR(NOT(ISNUMBER($A6)),AA6<0.000000000001),"",IF(Y6>=0,ACOS(MAX(-1,MIN(1,X6/AA6))),-ACOS(MAX(-1,MIN(1,X6/AA6))))) -> -1.4940415 | AD6: =IF(AB6="","",ACOS(AB6)) -> 0.8881174 | AE6: =IF(AC6="","",MOD(AC6+Geometry!$C$47*AD6+PI(),2*PI())-PI()) -> -0.6059241 | AF6: =IF(NOT(ISNUMBER($A6)),"",AND(AA6>=0.000000000001,ABS(Z6)<=AA6+0.00000001)) -> TRUE | AG6: =IF(AF6=FALSE,"",IF((Geometry!$C$28*COS(AE6)+Geometry!$C$32*SIN(AE6)+Geometry!$C$8*Geometry!$C$30*(1-COS(AE6)))>=0,1,-1)*ACOS(MAX(-1,MIN(1,(Geometry!$C$27*COS(AE6)+Geometry!$C$31*SIN(AE6)+Geometry!$C$7*Geometry!$C$30*(1-COS(AE6)))/SQRT((Geometry!$C$27*COS(AE6)+Geometry!$C$31*SIN(AE6)+Geometry!$C$7*Geometry!$C$30*(1-COS(AE6)))^2+(Geometry!$C$28*COS(AE6)+Geometry!$C$32*SIN(AE6)+Geometry!$C$8*Geometry!$C$30*(1-COS(AE6)))^2))))*180/PI()) -> -34.295911
A7: =IF(Inputs!$E$9+5*Inputs!$E$11<=Inputs!$E$10,Inputs!$E$9+5*Inputs!$E$11,"") -> -55 | B7: =IF(NOT(ISNUMBER($A7)),"",Inputs!$B$17+$A7*Inputs!$E$6/SQRT(Inputs!$E$6^2+Inputs!$E$7^2+Inputs!$E$8^2)) -> 919.873 | C7: =IF(NOT(ISNUMBER($A7)),"",Inputs!$C$17+$A7*Inputs!$E$7/SQRT(Inputs!$E$6^2+Inputs!$E$7^2+Inputs!$E$8^2)) -> 202.454 | D7: =IF(NOT(ISNUMBER($A7)),"",Inputs!$D$17+$A7*Inputs!$E$8/SQRT(Inputs!$E$6^2+Inputs!$E$7^2+Inputs!$E$8^2)) -> 182.189 | E7: =IF(NOT(ISNUMBER($A7)),"",Inputs!$B$15+Geometry!$B$15-B7) -> -24.932661 | F7: =IF(NOT(ISNUMBER($A7)),"",Inputs!$C$15+Geometry!$B$16-C7) -> 238.76798 | G7: =IF(NOT(ISNUMBER($A7)),"",Inputs!$D$15+Geometry!$B$17-D7) -> 11.015352 | H7: =IF(NOT(ISNUMBER($A7)),"",2*(E7*Geometry!$B$18+F7*Geometry!$B$19+G7*Geometry!$B$20)) -> 11564.375 | I7: =IF(NOT(ISNUMBER($A7)),"",2*(E7*Geometry!$B$21+F7*Geometry!$B$22+G7*Geometry!$B$23)) -> 70950.419 | J7: =IF(NOT(ISNUMBER($A7)),"",Geometry!$B$24^2-(E7^2+F7^2+G7^2)-(Geometry!$B$18^2+Geometry!$B$19^2+Geometry!$B$20^2)) -> -15913.295 | K7: =IF(NOT(ISNUMBER($A7)),"",SQRT(H7^2+I7^2)) -> 71886.694 | L7: =IF(OR(NOT(ISNUMBER($A7)),K7<0.000000000001),"",MAX(-1,MIN(1,J7/K7))) -> -0.22136634 | M7: =IF(OR(NOT(ISNUMBER($A7)),K7<0.000000000001),"",IF(I7>=0,ACOS(MAX(-1,MIN(1,H7/K7))),-ACOS(MAX(-1,MIN(1,H7/K7))))) -> 1.4092248 | N7: =IF(L7="","",ACOS(L7)) -> 1.7940117 | O7: =IF(M7="","",MOD(M7+Geometry!$B$47*N7+PI(),2*PI())-PI()) -> -0.3847869 | P7: =IF(NOT(ISNUMBER($A7)),"",AND(K7>=0.000000000001,ABS(J7)<=K7+0.00000001)) -> TRUE | Q7: =IF(P7=FALSE,"",IF((Geometry!$B$28*COS(O7)+Geometry!$B$32*SIN(O7)+Geometry!$B$8*Geometry!$B$30*(1-COS(O7)))>=0,1,-1)*ACOS(MAX(-1,MIN(1,(Geometry!$B$27*COS(O7)+Geometry!$B$31*SIN(O7)+Geometry!$B$7*Geometry!$B$30*(1-COS(O7)))/SQRT((Geometry!$B$27*COS(O7)+Geometry!$B$31*SIN(O7)+Geometry!$B$7*Geometry!$B$30*(1-COS(O7)))^2+(Geometry!$B$28*COS(O7)+Geometry!$B$32*SIN(O7)+Geometry!$B$8*Geometry!$B$30*(1-COS(O7)))^2))))*180/PI()) -> -21.621439 | R7: =IF(NOT(ISNUMBER($A7)),"",Inputs!$B$21+$A7*Inputs!$E$6/SQRT(Inputs!$E$6^2+Inputs!$E$7^2+Inputs!$E$8^2)) -> 919.873 | S7: =IF(NOT(ISNUMBER($A7)),"",Inputs!$C$21+$A7*Inputs!$E$7/SQRT(Inputs!$E$6^2+Inputs!$E$7^2+Inputs!$E$8^2)) -> -312.454 | T7: =IF(NOT(ISNUMBER($A7)),"",Inputs!$D$21+$A7*Inputs!$E$8/SQRT(Inputs!$E$6^2+Inputs!$E$7^2+Inputs!$E$8^2)) -> 182.189 | U7: =IF(NOT(ISNUMBER($A7)),"",Inputs!$B$19+Geometry!$C$15-R7) -> -24.932661 | V7: =IF(NOT(ISNUMBER($A7)),"",Inputs!$C$19+Geometry!$C$16-S7) -> -128.76798 | W7: =IF(NOT(ISNUMBER($A7)),"",Inputs!$D$19+Geometry!$C$17-T7) -> 11.015352 | X7: =IF(NOT(ISNUMBER($A7)),"",2*(U7*Geometry!$C$18+V7*Geometry!$C$19+W7*Geometry!$C$20)) -> 3087.992 | Y7: =IF(NOT(ISNUMBER($A7)),"",2*(U7*Geometry!$C$21+V7*Geometry!$C$22+W7*Geometry!$C$23)) -> -39437.359 | Z7: =IF(NOT(ISNUMBER($A7)),"",Geometry!$C$24^2-(U7^2+V7^2+W7^2)-(Geometry!$C$18^2+Geometry!$C$19^2+Geometry!$C$20^2)) -> 24515.662 | AA7: =IF(NOT(ISNUMBER($A7)),"",SQRT(X7^2+Y7^2)) -> 39558.071 | AB7: =IF(OR(NOT(ISNUMBER($A7)),AA7<0.000000000001),"",MAX(-1,MIN(1,Z7/AA7))) -> 0.61973856 | AC7: =IF(OR(NOT(ISNUMBER($A7)),AA7<0.000000000001),"",IF(Y7>=0,ACOS(MAX(-1,MIN(1,X7/AA7))),-ACOS(MAX(-1,MIN(1,X7/AA7))))) -> -1.4926546 | AD7: =IF(AB7="","",ACOS(AB7)) -> 0.90238679 | AE7: =IF(AC7="","",MOD(AC7+Geometry!$C$47*AD7+PI(),2*PI())-PI()) -> -0.59026778 | AF7: =IF(NOT(ISNUMBER($A7)),"",AND(AA7>=0.000000000001,ABS(Z7)<=AA7+0.00000001)) -> TRUE | AG7: =IF(AF7=FALSE,"",IF((Geometry!$C$28*COS(AE7)+Geometry!$C$32*SIN(AE7)+Geometry!$C$8*Geometry!$C$30*(1-COS(AE7)))>=0,1,-1)*ACOS(MAX(-1,MIN(1,(Geometry!$C$27*COS(AE7)+Geometry!$C$31*SIN(AE7)+Geometry!$C$7*Geometry!$C$30*(1-COS(AE7)))/SQRT((Geometry!$C$27*COS(AE7)+Geometry!$C$31*SIN(AE7)+Geometry!$C$7*Geometry!$C$30*(1-COS(AE7)))^2+(Geometry!$C$28*COS(AE7)+Geometry!$C$32*SIN(AE7)+Geometry!$C$8*Geometry!$C$30*(1-COS(AE7)))^2))))*180/PI()) -> -33.402925
A8: =IF(Inputs!$E$9+6*Inputs!$E$11<=Inputs!$E$10,Inputs!$E$9+6*Inputs!$E$11,"") -> -54 | B8: =IF(NOT(ISNUMBER($A8)),"",Inputs!$B$17+$A8*Inputs!$E$6/SQRT(Inputs!$E$6^2+Inputs!$E$7^2+Inputs!$E$8^2)) -> 919.873 | C8: =IF(NOT(ISNUMBER($A8)),"",Inputs!$C$17+$A8*Inputs!$E$7/SQRT(Inputs!$E$6^2+Inputs!$E$7^2+Inputs!$E$8^2)) -> 203.454 | D8: =IF(NOT(ISNUMBER($A8)),"",Inputs!$D$17+$A8*Inputs!$E$8/SQRT(Inputs!$E$6^2+Inputs!$E$7^2+Inputs!$E$8^2)) -> 182.189 | E8: =IF(NOT(ISNUMBER($A8)),"",Inputs!$B$15+Geometry!$B$15-B8) -> -24.932661 | F8: =IF(NOT(ISNUMBER($A8)),"",Inputs!$C$15+Geometry!$B$16-C8) -> 237.76798 | G8: =IF(NOT(ISNUMBER($A8)),"",Inputs!$D$15+Geometry!$B$17-D8) -> 11.015352 | H8: =IF(NOT(ISNUMBER($A8)),"",2*(E8*Geometry!$B$18+F8*Geometry!$B$19+G8*Geometry!$B$20)) -> 11487.317 | I8: =IF(NOT(ISNUMBER($A8)),"",2*(E8*Geometry!$B$21+F8*Geometry!$B$22+G8*Geometry!$B$23)) -> 70663.937 | J8: =IF(NOT(ISNUMBER($A8)),"",Geometry!$B$24^2-(E8^2+F8^2+G8^2)-(Geometry!$B$18^2+Geometry!$B$19^2+Geometry!$B$20^2)) -> -15436.759 | K8: =IF(NOT(ISNUMBER($A8)),"",SQRT(H8^2+I8^2)) -> 71591.553 | L8: =IF(OR(NOT(ISNUMBER($A8)),K8<0.000000000001),"",MAX(-1,MIN(1,J8/K8))) -> -0.21562263 | M8: =IF(OR(NOT(ISNUMBER($A8)),K8<0.000000000001),"",IF(I8>=0,ACOS(MAX(-1,MIN(1,H8/K8))),-ACOS(MAX(-1,MIN(1,H8/K8))))) -> 1.4096434 | N8: =IF(L8="","",ACOS(L8)) -> 1.7881257 | O8: =IF(M8="","",MOD(M8+Geometry!$B$47*N8+PI(),2*PI())-PI()) -> -0.37848236 | P8: =IF(NOT(ISNUMBER($A8)),"",AND(K8>=0.000000000001,ABS(J8)<=K8+0.00000001)) -> TRUE | Q8: =IF(P8=FALSE,"",IF((Geometry!$B$28*COS(O8)+Geometry!$B$32*SIN(O8)+Geometry!$B$8*Geometry!$B$30*(1-COS(O8)))>=0,1,-1)*ACOS(MAX(-1,MIN(1,(Geometry!$B$27*COS(O8)+Geometry!$B$31*SIN(O8)+Geometry!$B$7*Geometry!$B$30*(1-COS(O8)))/SQRT((Geometry!$B$27*COS(O8)+Geometry!$B$31*SIN(O8)+Geometry!$B$7*Geometry!$B$30*(1-COS(O8)))^2+(Geometry!$B$28*COS(O8)+Geometry!$B$32*SIN(O8)+Geometry!$B$8*Geometry!$B$30*(1-COS(O8)))^2))))*180/PI()) -> -21.266885 | R8: =IF(NOT(ISNUMBER($A8)),"",Inputs!$B$21+$A8*Inputs!$E$6/SQRT(Inputs!$E$6^2+Inputs!$E$7^2+Inputs!$E$8^2)) -> 919.873 | S8: =IF(NOT(ISNUMBER($A8)),"",Inputs!$C$21+$A8*Inputs!$E$7/SQRT(Inputs!$E$6^2+Inputs!$E$7^2+Inputs!$E$8^2)) -> -311.454 | T8: =IF(NOT(ISNUMBER($A8)),"",Inputs!$D$21+$A8*Inputs!$E$8/SQRT(Inputs!$E$6^2+Inputs!$E$7^2+Inputs!$E$8^2)) -> 182.189 | U8: =IF(NOT(ISNUMBER($A8)),"",Inputs!$B$19+Geometry!$C$15-R8) -> -24.932661 | V8: =IF(NOT(ISNUMBER($A8)),"",Inputs!$C$19+Geometry!$C$16-S8) -> -129.76798 | W8: =IF(NOT(ISNUMBER($A8)),"",Inputs!$D$19+Geometry!$C$17-T8) -> 11.015352 | X8: =IF(NOT(ISNUMBER($A8)),"",2*(U8*Geometry!$C$18+V8*Geometry!$C$19+W8*Geometry!$C$20)) -> 3165.05 | Y8: =IF(NOT(ISNUMBER($A8)),"",2*(U8*Geometry!$C$21+V8*Geometry!$C$22+W8*Geometry!$C$23)) -> -39723.841 | Z8: =IF(NOT(ISNUMBER($A8)),"",Geometry!$C$24^2-(U8^2+V8^2+W8^2)-(Geometry!$C$18^2+Geometry!$C$19^2+Geometry!$C$20^2)) -> 24257.126 | AA8: =IF(NOT(ISNUMBER($A8)),"",SQRT(X8^2+Y8^2)) -> 39849.732 | AB8: =IF(OR(NOT(ISNUMBER($A8)),AA8<0.000000000001),"",MAX(-1,MIN(1,Z8/AA8))) -> 0.60871491 | AC8: =IF(OR(NOT(ISNUMBER($A8)),AA8<0.000000000001),"",IF(Y8>=0,ACOS(MAX(-1,MIN(1,X8/AA8))),-ACOS(MAX(-1,MIN(1,X8/AA8))))) -> -1.491288 | AD8: =IF(AB8="","",ACOS(AB8)) -> 0.91635649 | AE8: =IF(AC8="","",MOD(AC8+Geometry!$C$47*AD8+PI(),2*PI())-PI()) -> -0.57493147 | AF8: =IF(NOT(ISNUMBER($A8)),"",AND(AA8>=0.000000000001,ABS(Z8)<=AA8+0.00000001)) -> TRUE | AG8: =IF(AF8=FALSE,"",IF((Geometry!$C$28*COS(AE8)+Geometry!$C$32*SIN(AE8)+Geometry!$C$8*Geometry!$C$30*(1-COS(AE8)))>=0,1,-1)*ACOS(MAX(-1,MIN(1,(Geometry!$C$27*COS(AE8)+Geometry!$C$31*SIN(AE8)+Geometry!$C$7*Geometry!$C$30*(1-COS(AE8)))/SQRT((Geometry!$C$27*COS(AE8)+Geometry!$C$31*SIN(AE8)+Geometry!$C$7*Geometry!$C$30*(1-COS(AE8)))^2+(Geometry!$C$28*COS(AE8)+Geometry!$C$32*SIN(AE8)+Geometry!$C$8*Geometry!$C$30*(1-COS(AE8)))^2))))*180/PI()) -> -32.528558
A9: =IF(Inputs!$E$9+7*Inputs!$E$11<=Inputs!$E$10,Inputs!$E$9+7*Inputs!$E$11,"") -> -53 | B9: =IF(NOT(ISNUMBER($A9)),"",Inputs!$B$17+$A9*Inputs!$E$6/SQRT(Inputs!$E$6^2+Inputs!$E$7^2+Inputs!$E$8^2)) -> 919.873 | C9: =IF(NOT(ISNUMBER($A9)),"",Inputs!$C$17+$A9*Inputs!$E$7/SQRT(Inputs!$E$6^2+Inputs!$E$7^2+Inputs!$E$8^2)) -> 204.454 | D9: =IF(NOT(ISNUMBER($A9)),"",Inputs!$D$17+$A9*Inputs!$E$8/SQRT(Inputs!$E$6^2+Inputs!$E$7^2+Inputs!$E$8^2)) -> 182.189 | E9: =IF(NOT(ISNUMBER($A9)),"",Inputs!$B$15+Geometry!$B$15-B9) -> -24.932661 | F9: =IF(NOT(ISNUMBER($A9)),"",Inputs!$C$15+Geometry!$B$16-C9) -> 236.76798 | G9: =IF(NOT(ISNUMBER($A9)),"",Inputs!$D$15+Geometry!$B$17-D9) -> 11.015352 | H9: =IF(NOT(ISNUMBER($A9)),"",2*(E9*Geometry!$B$18+F9*Geometry!$B$19+G9*Geometry!$B$20)) -> 11410.259 | I9: =IF(NOT(ISNUMBER($A9)),"",2*(E9*Geometry!$B$21+F9*Geometry!$B$22+G9*Geometry!$B$23)) -> 70377.454 | J9: =IF(NOT(ISNUMBER($A9)),"",Geometry!$B$24^2-(E9^2+F9^2+G9^2)-(Geometry!$B$18^2+Geometry!$B$19^2+Geometry!$B$20^2)) -> -14962.223 | K9: =IF(NOT(ISNUMBER($A9)),"",SQRT(H9^2+I9^2)) -> 71296.424 | L9: =IF(OR(NOT(ISNUMBER($A9)),K9<0.000000000001),"",MAX(-1,MIN(1,J9/K9))) -> -0.20985937 | M9: =IF(OR(NOT(ISNUMBER($A9)),K9<0.000000000001),"",IF(I9>=0,ACOS(MAX(-1,MIN(1,H9/K9))),-ACOS(MAX(-1,MIN(1,H9/K9))))) -> 1.4100654 | N9: =IF(L9="","",ACOS(L9)) -> 1.7822275 | O9: =IF(M9="","",MOD(M9+Geometry!$B$47*N9+PI(),2*PI())-PI()) -> -0.37216201 | P9: =IF(NOT(ISNUMBER($A9)),"",AND(K9>=0.000000000001,ABS(J9)<=K9+0.00000001)) -> TRUE | Q9: =IF(P9=FALSE,"",IF((Geometry!$B$28*COS(O9)+Geometry!$B$32*SIN(O9)+Geometry!$B$8*Geometry!$B$30*(1-COS(O9)))>=0,1,-1)*ACOS(MAX(-1,MIN(1,(Geometry!$B$27*COS(O9)+Geometry!$B$31*SIN(O9)+Geometry!$B$7*Geometry!$B$30*(1-COS(O9)))/SQRT((Geometry!$B$27*COS(O9)+Geometry!$B$31*SIN(O9)+Geometry!$B$7*Geometry!$B$30*(1-COS(O9)))^2+(Geometry!$B$28*COS(O9)+Geometry!$B$32*SIN(O9)+Geometry!$B$8*Geometry!$B$30*(1-COS(O9)))^2))))*180/PI()) -> -20.911473 | R9: =IF(NOT(ISNUMBER($A9)),"",Inputs!$B$21+$A9*Inputs!$E$6/SQRT(Inputs!$E$6^2+Inputs!$E$7^2+Inputs!$E$8^2)) -> 919.873 | S9: =IF(NOT(ISNUMBER($A9)),"",Inputs!$C$21+$A9*Inputs!$E$7/SQRT(Inputs!$E$6^2+Inputs!$E$7^2+Inputs!$E$8^2)) -> -310.454 | T9: =IF(NOT(ISNUMBER($A9)),"",Inputs!$D$21+$A9*Inputs!$E$8/SQRT(Inputs!$E$6^2+Inputs!$E$7^2+Inputs!$E$8^2)) -> 182.189 | U9: =IF(NOT(ISNUMBER($A9)),"",Inputs!$B$19+Geometry!$C$15-R9) -> -24.932661 | V9: =IF(NOT(ISNUMBER($A9)),"",Inputs!$C$19+Geometry!$C$16-S9) -> -130.76798 | W9: =IF(NOT(ISNUMBER($A9)),"",Inputs!$D$19+Geometry!$C$17-T9) -> 11.015352 | X9: =IF(NOT(ISNUMBER($A9)),"",2*(U9*Geometry!$C$18+V9*Geometry!$C$19+W9*Geometry!$C$20)) -> 3242.108 | Y9: =IF(NOT(ISNUMBER($A9)),"",2*(U9*Geometry!$C$21+V9*Geometry!$C$22+W9*Geometry!$C$23)) -> -40010.324 | Z9: =IF(NOT(ISNUMBER($A9)),"",Geometry!$C$24^2-(U9^2+V9^2+W9^2)-(Geometry!$C$18^2+Geometry!$C$19^2+Geometry!$C$20^2)) -> 23996.59 | AA9: =IF(NOT(ISNUMBER($A9)),"",SQRT(X9^2+Y9^2)) -> 40141.466 | AB9: =IF(OR(NOT(ISNUMBER($A9)),AA9<0.000000000001),"",MAX(-1,MIN(1,Z9/AA9))) -> 0.59780054 | AC9: =IF(OR(NOT(ISNUMBER($A9)),AA9<0.000000000001),"",IF(Y9>=0,ACOS(MAX(-1,MIN(1,X9/AA9))),-ACOS(MAX(-1,MIN(1,X9/AA9))))) -> -1.4899412 | AD9: =IF(AB9="","",ACOS(AB9)) -> 0.93004171 | AE9: =IF(AC9="","",MOD(AC9+Geometry!$C$47*AD9+PI(),2*PI())-PI()) -> -0.55989949 | AF9: =IF(NOT(ISNUMBER($A9)),"",AND(AA9>=0.000000000001,ABS(Z9)<=AA9+0.00000001)) -> TRUE | AG9: =IF(AF9=FALSE,"",IF((Geometry!$C$28*COS(AE9)+Geometry!$C$32*SIN(AE9)+Geometry!$C$8*Geometry!$C$30*(1-COS(AE9)))>=0,1,-1)*ACOS(MAX(-1,MIN(1,(Geometry!$C$27*COS(AE9)+Geometry!$C$31*SIN(AE9)+Geometry!$C$7*Geometry!$C$30*(1-COS(AE9)))/SQRT((Geometry!$C$27*COS(AE9)+Geometry!$C$31*SIN(AE9)+Geometry!$C$7*Geometry!$C$30*(1-COS(AE9)))^2+(Geometry!$C$28*COS(AE9)+Geometry!$C$32*SIN(AE9)+Geometry!$C$8*Geometry!$C$30*(1-COS(AE9)))^2))))*180/PI()) -> -31.671897
A10: =IF(Inputs!$E$9+8*Inputs!$E$11<=Inputs!$E$10,Inputs!$E$9+8*Inputs!$E$11,"") -> -52 | B10: =IF(NOT(ISNUMBER($A10)),"",Inputs!$B$17+$A10*Inputs!$E$6/SQRT(Inputs!$E$6^2+Inputs!$E$7^2+Inputs!$E$8^2)) -> 919.873 | C10: =IF(NOT(ISNUMBER($A10)),"",Inputs!$C$17+$A10*Inputs!$E$7/SQRT(Inputs!$E$6^2+Inputs!$E$7^2+Inputs!$E$8^2)) -> 205.454 | D10: =IF(NOT(ISNUMBER($A10)),"",Inputs!$D$17+$A10*Inputs!$E$8/SQRT(Inputs!$E$6^2+Inputs!$E$7^2+Inputs!$E$8^2)) -> 182.189 | E10: =IF(NOT(ISNUMBER($A10)),"",Inputs!$B$15+Geometry!$B$15-B10) -> -24.932661 | F10: =IF(NOT(ISNUMBER($A10)),"",Inputs!$C$15+Geometry!$B$16-C10) -> 235.76798 | G10: =IF(NOT(ISNUMBER($A10)),"",Inputs!$D$15+Geometry!$B$17-D10) -> 11.015352 | H10: =IF(NOT(ISNUMBER($A10)),"",2*(E10*Geometry!$B$18+F10*Geometry!$B$19+G10*Geometry!$B$20)) -> 11333.201 | I10: =IF(NOT(ISNUMBER($A10)),"",2*(E10*Geometry!$B$21+F10*Geometry!$B$22+G10*Geometry!$B$23)) -> 70090.972 | J10: =IF(NOT(ISNUMBER($A10)),"",Geometry!$B$24^2-(E10^2+F10^2+G10^2)-(Geometry!$B$18^2+Geometry!$B$19^2+Geometry!$B$20^2)) -> -14489.687 | K10: =IF(NOT(ISNUMBER($A10)),"",SQRT(H10^2+I10^2)) -> 71001.309 | L10: =IF(OR(NOT(ISNUMBER($A10)),K10<0.000000000001),"",MAX(-1,MIN(1,J10/K10))) -> -0.20407633 | M10: =IF(OR(NOT(ISNUMBER($A10)),K10<0.000000000001),"",IF(I10>=0,ACOS(MAX(-1,MIN(1,H10/K10))),-ACOS(MAX(-1,MIN(1,H10/K10))))) -> 1.410491 | N10: =IF(L10="","",ACOS(L10)) -> 1.7763164 | O10: =IF(M10="","",MOD(M10+Geometry!$B$47*N10+PI(),2*PI())-PI()) -> -0.3658254 | P10: =IF(NOT(ISNUMBER($A10)),"",AND(K10>=0.000000000001,ABS(J10)<=K10+0.00000001)) -> TRUE | Q10: =IF(P10=FALSE,"",IF((Geometry!$B$28*COS(O10)+Geometry!$B$32*SIN(O10)+Geometry!$B$8*Geometry!$B$30*(1-COS(O10)))>=0,1,-1)*ACOS(MAX(-1,MIN(1,(Geometry!$B$27*COS(O10)+Geometry!$B$31*SIN(O10)+Geometry!$B$7*Geometry!$B$30*(1-COS(O10)))/SQRT((Geometry!$B$27*COS(O10)+Geometry!$B$31*SIN(O10)+Geometry!$B$7*Geometry!$B$30*(1-COS(O10)))^2+(Geometry!$B$28*COS(O10)+Geometry!$B$32*SIN(O10)+Geometry!$B$8*Geometry!$B$30*(1-COS(O10)))^2))))*180/PI()) -> -20.555175 | R10: =IF(NOT(ISNUMBER($A10)),"",Inputs!$B$21+$A10*Inputs!$E$6/SQRT(Inputs!$E$6^2+Inputs!$E$7^2+Inputs!$E$8^2)) -> 919.873 | S10: =IF(NOT(ISNUMBER($A10)),"",Inputs!$C$21+$A10*Inputs!$E$7/SQRT(Inputs!$E$6^2+Inputs!$E$7^2+Inputs!$E$8^2)) -> -309.454 | T10: =IF(NOT(ISNUMBER($A10)),"",Inputs!$D$21+$A10*Inputs!$E$8/SQRT(Inputs!$E$6^2+Inputs!$E$7^2+Inputs!$E$8^2)) -> 182.189 | U10: =IF(NOT(ISNUMBER($A10)),"",Inputs!$B$19+Geometry!$C$15-R10) -> -24.932661 | V10: =IF(NOT(ISNUMBER($A10)),"",Inputs!$C$19+Geometry!$C$16-S10) -> -131.76798 | W10: =IF(NOT(ISNUMBER($A10)),"",Inputs!$D$19+Geometry!$C$17-T10) -> 11.015352 | X10: =IF(NOT(ISNUMBER($A10)),"",2*(U10*Geometry!$C$18+V10*Geometry!$C$19+W10*Geometry!$C$20)) -> 3319.1661 | Y10: =IF(NOT(ISNUMBER($A10)),"",2*(U10*Geometry!$C$21+V10*Geometry!$C$22+W10*Geometry!$C$23)) -> -40296.806 | Z10: =IF(NOT(ISNUMBER($A10)),"",Geometry!$C$24^2-(U10^2+V10^2+W10^2)-(Geometry!$C$18^2+Geometry!$C$19^2+Geometry!$C$20^2)) -> 23734.054 | AA10: =IF(NOT(ISNUMBER($A10)),"",SQRT(X10^2+Y10^2)) -> 40433.272 | AB10: =IF(OR(NOT(ISNUMBER($A10)),AA10<0.000000000001),"",MAX(-1,MIN(1,Z10/AA10))) -> 0.58699316 | AC10: =IF(OR(NOT(ISNUMBER($A10)),AA10<0.000000000001),"",IF(Y10>=0,ACOS(MAX(-1,MIN(1,X10/AA10))),-ACOS(MAX(-1,MIN(1,X10/AA10))))) -> -1.4886139 | AD10: =IF(AB10="","",ACOS(AB10)) -> 0.94345652 | AE10: =IF(AC10="","",MOD(AC10+Geometry!$C$47*AD10+PI(),2*PI())-PI()) -> -0.54515736 | AF10: =IF(NOT(ISNUMBER($A10)),"",AND(AA10>=0.000000000001,ABS(Z10)<=AA10+0.00000001)) -> TRUE | AG10: =IF(AF10=FALSE,"",IF((Geometry!$C$28*COS(AE10)+Geometry!$C$32*SIN(AE10)+Geometry!$C$8*Geometry!$C$30*(1-COS(AE10)))>=0,1,-1)*ACOS(MAX(-1,MIN(1,(Geometry!$C$27*COS(AE10)+Geometry!$C$31*SIN(AE10)+Geometry!$C$7*Geometry!$C$30*(1-COS(AE10)))/SQRT((Geometry!$C$27*COS(AE10)+Geometry!$C$31*SIN(AE10)+Geometry!$C$7*Geometry!$C$30*(1-COS(AE10)))^2+(Geometry!$C$28*COS(AE10)+Geometry!$C$32*SIN(AE10)+Geometry!$C$8*Geometry!$C$30*(1-COS(AE10)))^2))))*180/PI()) -> -30.832098
A11: =IF(Inputs!$E$9+9*Inputs!$E$11<=Inputs!$E$10,Inputs!$E$9+9*Inputs!$E$11,"") -> -51 | B11: =IF(NOT(ISNUMBER($A11)),"",Inputs!$B$17+$A11*Inputs!$E$6/SQRT(Inputs!$E$6^2+Inputs!$E$7^2+Inputs!$E$8^2)) -> 919.873 | C11: =IF(NOT(ISNUMBER($A11)),"",Inputs!$C$17+$A11*Inputs!$E$7/SQRT(Inputs!$E$6^2+Inputs!$E$7^2+Inputs!$E$8^2)) -> 206.454 | D11: =IF(NOT(ISNUMBER($A11)),"",Inputs!$D$17+$A11*Inputs!$E$8/SQRT(Inputs!$E$6^2+Inputs!$E$7^2+Inputs!$E$8^2)) -> 182.189 | E11: =IF(NOT(ISNUMBER($A11)),"",Inputs!$B$15+Geometry!$B$15-B11) -> -24.932661 | F11: =IF(NOT(ISNUMBER($A11)),"",Inputs!$C$15+Geometry!$B$16-C11) -> 234.76798 | G11: =IF(NOT(ISNUMBER($A11)),"",Inputs!$D$15+Geometry!$B$17-D11) -> 11.015352 | H11: =IF(NOT(ISNUMBER($A11)),"",2*(E11*Geometry!$B$18+F11*Geometry!$B$19+G11*Geometry!$B$20)) -> 11256.143 | I11: =IF(NOT(ISNUMBER($A11)),"",2*(E11*Geometry!$B$21+F11*Geometry!$B$22+G11*Geometry!$B$23)) -> 69804.49 | J11: =IF(NOT(ISNUMBER($A11)),"",Geometry!$B$24^2-(E11^2+F11^2+G11^2)-(Geometry!$B$18^2+Geometry!$B$19^2+Geometry!$B$20^2)) -> -14019.151 | K11: =IF(NOT(ISNUMBER($A11)),"",SQRT(H11^2+I11^2)) -> 70706.206 | L11: =IF(OR(NOT(ISNUMBER($A11)),K11<0.000000000001),"",MAX(-1,MIN(1,J11/K11))) -> -0.19827327 | M11: =IF(OR(NOT(ISNUMBER($A11)),K11<0.000000000001),"",IF(I11>=0,ACOS(MAX(-1,MIN(1,H11/K11))),-ACOS(MAX(-1,MIN(1,H11/K11))))) -> 1.4109201 | N11: =IF(L11="","",ACOS(L11)) -> 1.7703922 | O11: =IF(M11="","",MOD(M11+Geometry!$B$47*N11+PI(),2*PI())-PI()) -> -0.35947209 | P11: =IF(NOT(ISNUMBER($A11)),"",AND(K11>=0.000000000001,ABS(J11)<=K11+0.00000001)) -> TRUE | Q11: =IF(P11=FALSE,"",IF((Geometry!$B$28*COS(O11)+Geometry!$B$32*SIN(O11)+Geometry!$B$8*Geometry!$B$30*(1-COS(O11)))>=0,1,-1)*ACOS(MAX(-1,MIN(1,(Geometry!$B$27*COS(O11)+Geometry!$B$31*SIN(O11)+Geometry!$B$7*Geometry!$B$30*(1-COS(O11)))/SQRT((Geometry!$B$27*COS(O11)+Geometry!$B$31*SIN(O11)+Geometry!$B$7*Geometry!$B$30*(1-COS(O11)))^2+(Geometry!$B$28*COS(O11)+Geometry!$B$32*SIN(O11)+Geometry!$B$8*Geometry!$B$30*(1-COS(O11)))^2))))*180/PI()) -> -20.197967 | R11: =IF(NOT(ISNUMBER($A11)),"",Inputs!$B$21+$A11*Inputs!$E$6/SQRT(Inputs!$E$6^2+Inputs!$E$7^2+Inputs!$E$8^2)) -> 919.873 | S11: =IF(NOT(ISNUMBER($A11)),"",Inputs!$C$21+$A11*Inputs!$E$7/SQRT(Inputs!$E$6^2+Inputs!$E$7^2+Inputs!$E$8^2)) -> -308.454 | T11: =IF(NOT(ISNUMBER($A11)),"",Inputs!$D$21+$A11*Inputs!$E$8/SQRT(Inputs!$E$6^2+Inputs!$E$7^2+Inputs!$E$8^2)) -> 182.189 | U11: =IF(NOT(ISNUMBER($A11)),"",Inputs!$B$19+Geometry!$C$15-R11) -> -24.932661 | V11: =IF(NOT(ISNUMBER($A11)),"",Inputs!$C$19+Geometry!$C$16-S11) -> -132.76798 | W11: =IF(NOT(ISNUMBER($A11)),"",Inputs!$D$19+Geometry!$C$17-T11) -> 11.015352 | X11: =IF(NOT(ISNUMBER($A11)),"",2*(U11*Geometry!$C$18+V11*Geometry!$C$19+W11*Geometry!$C$20)) -> 3396.2241 | Y11: =IF(NOT(ISNUMBER($A11)),"",2*(U11*Geometry!$C$21+V11*Geometry!$C$22+W11*Geometry!$C$23)) -> -40583.289 | Z11: =IF(NOT(ISNUMBER($A11)),"",Geometry!$C$24^2-(U11^2+V11^2+W11^2)-(Geometry!$C$18^2+Geometry!$C$19^2+Geometry!$C$20^2)) -> 23469.518 | AA11: =IF(NOT(ISNUMBER($A11)),"",SQRT(X11^2+Y11^2)) -> 40725.148 | AB11: =IF(OR(NOT(ISNUMBER($A11)),AA11<0.000000000001),"",MAX(-1,MIN(1,Z11/AA11))) -> 0.57629056 | AC11: =IF(OR(NOT(ISNUMBER($A11)),AA11<0.000000000001),"",IF(Y11>=0,ACOS(MAX(-1,MIN(1,X11/AA11))),-ACOS(MAX(-1,MIN(1,X11/AA11))))) -> -1.4873056 | AD11: =IF(AB11="","",ACOS(AB11)) -> 0.9566139 | AE11: =IF(AC11="","",MOD(AC11+Geometry!$C$47*AD11+PI(),2*PI())-PI()) -> -0.53069168 | AF11: =IF(NOT(ISNUMBER($A11)),"",AND(AA11>=0.000000000001,ABS(Z11)<=AA11+0.00000001)) -> TRUE | AG11: =IF(AF11=FALSE,"",IF((Geometry!$C$28*COS(AE11)+Geometry!$C$32*SIN(AE11)+Geometry!$C$8*Geometry!$C$30*(1-COS(AE11)))>=0,1,-1)*ACOS(MAX(-1,MIN(1,(Geometry!$C$27*COS(AE11)+Geometry!$C$31*SIN(AE11)+Geometry!$C$7*Geometry!$C$30*(1-COS(AE11)))/SQRT((Geometry!$C$27*COS(AE11)+Geometry!$C$31*SIN(AE11)+Geometry!$C$7*Geometry!$C$30*(1-COS(AE11)))^2+(Geometry!$C$28*COS(AE11)+Geometry!$C$32*SIN(AE11)+Geometry!$C$8*Geometry!$C$30*(1-COS(AE11)))^2))))*180/PI()) -> -30.00838
A12: =IF(Inputs!$E$9+10*Inputs!$E$11<=Inputs!$E$10,Inputs!$E$9+10*Inputs!$E$11,"") -> -50 | B12: =IF(NOT(ISNUMBER($A12)),"",Inputs!$B$17+$A12*Inputs!$E$6/SQRT(Inputs!$E$6^2+Inputs!$E$7^2+Inputs!$E$8^2)) -> 919.873 | C12: =IF(NOT(ISNUMBER($A12)),"",Inputs!$C$17+$A12*Inputs!$E$7/SQRT(Inputs!$E$6^2+Inputs!$E$7^2+Inputs!$E$8^2)) -> 207.454 | D12: =IF(NOT(ISNUMBER($A12)),"",Inputs!$D$17+$A12*Inputs!$E$8/SQRT(Inputs!$E$6^2+Inputs!$E$7^2+Inputs!$E$8^2)) -> 182.189 | E12: =IF(NOT(ISNUMBER($A12)),"",Inputs!$B$15+Geometry!$B$15-B12) -> -24.932661 | F12: =IF(NOT(ISNUMBER($A12)),"",Inputs!$C$15+Geometry!$B$16-C12) -> 233.76798 | G12: =IF(NOT(ISNUMBER($A12)),"",Inputs!$D$15+Geometry!$B$17-D12) -> 11.015352 | H12: =IF(NOT(ISNUMBER($A12)),"",2*(E12*Geometry!$B$18+F12*Geometry!$B$19+G12*Geometry!$B$20)) -> 11179.085 | I12: =IF(NOT(ISNUMBER($A12)),"",2*(E12*Geometry!$B$21+F12*Geometry!$B$22+G12*Geometry!$B$23)) -> 69518.007 | J12: =IF(NOT(ISNUMBER($A12)),"",Geometry!$B$24^2-(E12^2+F12^2+G12^2)-(Geometry!$B$18^2+Geometry!$B$19^2+Geometry!$B$20^2)) -> -13550.615 | K12: =IF(NOT(ISNUMBER($A12)),"",SQRT(H12^2+I12^2)) -> 70411.116 | L12: =IF(OR(NOT(ISNUMBER($A12)),K12<0.000000000001),"",MAX(-1,MIN(1,J12/K12))) -> -0.19244994 | M12: =IF(OR(NOT(ISNUMBER($A12)),K12<0.000000000001),"",IF(I12>=0,ACOS(MAX(-1,MIN(1,H12/K12))),-ACOS(MAX(-1,MIN(1,H12/K12))))) -> 1.4113529 | N12: =IF(L12="","",ACOS(L12)) -> 1.7644545 | O12: =IF(M12="","",MOD(M12+Geometry!$B$47*N12+PI(),2*PI())-PI()) -> -0.35310161 | P12: =IF(NOT(ISNUMBER($A12)),"",AND(K12>=0.000000000001,ABS(J12)<=K12+0.00000001)) -> TRUE | Q12: =IF(P12=FALSE,"",IF((Geometry!$B$28*COS(O12)+Geometry!$B$32*SIN(O12)+Geometry!$B$8*Geometry!$B$30*(1-COS(O12)))>=0,1,-1)*ACOS(MAX(-1,MIN(1,(Geometry!$B$27*COS(O12)+Geometry!$B$31*SIN(O12)+Geometry!$B$7*Geometry!$B$30*(1-COS(O12)))/SQRT((Geometry!$B$27*COS(O12)+Geometry!$B$31*SIN(O12)+Geometry!$B$7*Geometry!$B$30*(1-COS(O12)))^2+(Geometry!$B$28*COS(O12)+Geometry!$B$32*SIN(O12)+Geometry!$B$8*Geometry!$B$30*(1-COS(O12)))^2))))*180/PI()) -> -19.83982 | R12: =IF(NOT(ISNUMBER($A12)),"",Inputs!$B$21+$A12*Inputs!$E$6/SQRT(Inputs!$E$6^2+Inputs!$E$7^2+Inputs!$E$8^2)) -> 919.873 | S12: =IF(NOT(ISNUMBER($A12)),"",Inputs!$C$21+$A12*Inputs!$E$7/SQRT(Inputs!$E$6^2+Inputs!$E$7^2+Inputs!$E$8^2)) -> -307.454 | T12: =IF(NOT(ISNUMBER($A12)),"",Inputs!$D$21+$A12*Inputs!$E$8/SQRT(Inputs!$E$6^2+Inputs!$E$7^2+Inputs!$E$8^2)) -> 182.189 | U12: =IF(NOT(ISNUMBER($A12)),"",Inputs!$B$19+Geometry!$C$15-R12) -> -24.932661 | V12: =IF(NOT(ISNUMBER($A12)),"",Inputs!$C$19+Geometry!$C$16-S12) -> -133.76798 | W12: =IF(NOT(ISNUMBER($A12)),"",Inputs!$D$19+Geometry!$C$17-T12) -> 11.015352 | X12: =IF(NOT(ISNUMBER($A12)),"",2*(U12*Geometry!$C$18+V12*Geometry!$C$19+W12*Geometry!$C$20)) -> 3473.2821 | Y12: =IF(NOT(ISNUMBER($A12)),"",2*(U12*Geometry!$C$21+V12*Geometry!$C$22+W12*Geometry!$C$23)) -> -40869.771 | Z12: =IF(NOT(ISNUMBER($A12)),"",Geometry!$C$24^2-(U12^2+V12^2+W12^2)-(Geometry!$C$18^2+Geometry!$C$19^2+Geometry!$C$20^2)) -> 23202.982 | AA12: =IF(NOT(ISNUMBER($A12)),"",SQRT(X12^2+Y12^2)) -> 41017.092 | AB12: =IF(OR(NOT(ISNUMBER($A12)),AA12<0.000000000001),"",MAX(-1,MIN(1,Z12/AA12))) -> 0.56569056 | AC12: =IF(OR(NOT(ISNUMBER($A12)),AA12<0.000000000001),"",IF(Y12>=0,ACOS(MAX(-1,MIN(1,X12/AA12))),-ACOS(MAX(-1,MIN(1,X12/AA12))))) -> -1.4860159 | AD12: =IF(AB12="","",ACOS(AB12)) -> 0.96952588 | AE12: =IF(AC12="","",MOD(AC12+Geometry!$C$47*AD12+PI(),2*PI())-PI()) -> -0.51649003 | AF12: =IF(NOT(ISNUMBER($A12)),"",AND(AA12>=0.000000000001,ABS(Z12)<=AA12+0.00000001)) -> TRUE | AG12: =IF(AF12=FALSE,"",IF((Geometry!$C$28*COS(AE12)+Geometry!$C$32*SIN(AE12)+Geometry!$C$8*Geometry!$C$30*(1-COS(AE12)))>=0,1,-1)*ACOS(MAX(-1,MIN(1,(Geometry!$C$27*COS(AE12)+Geometry!$C$31*SIN(AE12)+Geometry!$C$7*Geometry!$C$30*(1-COS(AE12)))/SQRT((Geometry!$C$27*COS(AE12)+Geometry!$C$31*SIN(AE12)+Geometry!$C$7*Geometry!$C$30*(1-COS(AE12)))^2+(Geometry!$C$28*COS(AE12)+Geometry!$C$32*SIN(AE12)+Geometry!$C$8*Geometry!$C$30*(1-COS(AE12)))^2))))*180/PI()) -> -29.200018
A13: =IF(Inputs!$E$9+11*Inputs!$E$11<=Inputs!$E$10,Inputs!$E$9+11*Inputs!$E$11,"") -> -49 | B13: =IF(NOT(ISNUMBER($A13)),"",Inputs!$B$17+$A13*Inputs!$E$6/SQRT(Inputs!$E$6^2+Inputs!$E$7^2+Inputs!$E$8^2)) -> 919.873 | C13: =IF(NOT(ISNUMBER($A13)),"",Inputs!$C$17+$A13*Inputs!$E$7/SQRT(Inputs!$E$6^2+Inputs!$E$7^2+Inputs!$E$8^2)) -> 208.454 | D13: =IF(NOT(ISNUMBER($A13)),"",Inputs!$D$17+$A13*Inputs!$E$8/SQRT(Inputs!$E$6^2+Inputs!$E$7^2+Inputs!$E$8^2)) -> 182.189 | E13: =IF(NOT(ISNUMBER($A13)),"",Inputs!$B$15+Geometry!$B$15-B13) -> -24.932661 | F13: =IF(NOT(ISNUMBER($A13)),"",Inputs!$C$15+Geometry!$B$16-C13) -> 232.76798 | G13: =IF(NOT(ISNUMBER($A13)),"",Inputs!$D$15+Geometry!$B$17-D13) -> 11.015352 | H13: =IF(NOT(ISNUMBER($A13)),"",2*(E13*Geometry!$B$18+F13*Geometry!$B$19+G13*Geometry!$B$20)) -> 11102.027 | I13: =IF(NOT(ISNUMBER($A13)),"",2*(E13*Geometry!$B$21+F13*Geometry!$B$22+G13*Geometry!$B$23)) -> 69231.525 | J13: =IF(NOT(ISNUMBER($A13)),"",Geometry!$B$24^2-(E13^2+F13^2+G13^2)-(Geometry!$B$18^2+Geometry!$B$19^2+Geometry!$B$20^2)) -> -13084.079 | K13: =IF(NOT(ISNUMBER($A13)),"",SQRT(H13^2+I13^2)) -> 70116.04 | L13: =IF(OR(NOT(ISNUMBER($A13)),K13<0.000000000001),"",MAX(-1,MIN(1,J13/K13))) -> -0.18660607 | M13: =IF(OR(NOT(ISNUMBER($A13)),K13<0.000000000001),"",IF(I13>=0,ACOS(MAX(-1,MIN(1,H13/K13))),-ACOS(MAX(-1,MIN(1,H13/K13))))) -> 1.4117892 | N13: =IF(L13="","",ACOS(L13)) -> 1.7585027 | O13: =IF(M13="","",MOD(M13+Geometry!$B$47*N13+PI(),2*PI())-PI()) -> -0.3467135 | P13: =IF(NOT(ISNUMBER($A13)),"",AND(K13>=0.000000000001,ABS(J13)<=K13+0.00000001)) -> TRUE | Q13: =IF(P13=FALSE,"",IF((Geometry!$B$28*COS(O13)+Geometry!$B$32*SIN(O13)+Geometry!$B$8*Geometry!$B$30*(1-COS(O13)))>=0,1,-1)*ACOS(MAX(-1,MIN(1,(Geometry!$B$27*COS(O13)+Geometry!$B$31*SIN(O13)+Geometry!$B$7*Geometry!$B$30*(1-COS(O13)))/SQRT((Geometry!$B$27*COS(O13)+Geometry!$B$31*SIN(O13)+Geometry!$B$7*Geometry!$B$30*(1-COS(O13)))^2+(Geometry!$B$28*COS(O13)+Geometry!$B$32*SIN(O13)+Geometry!$B$8*Geometry!$B$30*(1-COS(O13)))^2))))*180/PI()) -> -19.480709 | R13: =IF(NOT(ISNUMBER($A13)),"",Inputs!$B$21+$A13*Inputs!$E$6/SQRT(Inputs!$E$6^2+Inputs!$E$7^2+Inputs!$E$8^2)) -> 919.873 | S13: =IF(NOT(ISNUMBER($A13)),"",Inputs!$C$21+$A13*Inputs!$E$7/SQRT(Inputs!$E$6^2+Inputs!$E$7^2+Inputs!$E$8^2)) -> -306.454 | T13: =IF(NOT(ISNUMBER($A13)),"",Inputs!$D$21+$A13*Inputs!$E$8/SQRT(Inputs!$E$6^2+Inputs!$E$7^2+Inputs!$E$8^2)) -> 182.189 | U13: =IF(NOT(ISNUMBER($A13)),"",Inputs!$B$19+Geometry!$C$15-R13) -> -24.932661 | V13: =IF(NOT(ISNUMBER($A13)),"",Inputs!$C$19+Geometry!$C$16-S13) -> -134.76798 | W13: =IF(NOT(ISNUMBER($A13)),"",Inputs!$D$19+Geometry!$C$17-T13) -> 11.015352 | X13: =IF(NOT(ISNUMBER($A13)),"",2*(U13*Geometry!$C$18+V13*Geometry!$C$19+W13*Geometry!$C$20)) -> 3550.3402 | Y13: =IF(NOT(ISNUMBER($A13)),"",2*(U13*Geometry!$C$21+V13*Geometry!$C$22+W13*Geometry!$C$23)) -> -41156.253 | Z13: =IF(NOT(ISNUMBER($A13)),"",Geometry!$C$24^2-(U13^2+V13^2+W13^2)-(Geometry!$C$18^2+Geometry!$C$19^2+Geometry!$C$20^2)) -> 22934.446 | AA13: =IF(NOT(ISNUMBER($A13)),"",SQRT(X13^2+Y13^2)) -> 41309.104 | AB13: =IF(OR(NOT(ISNUMBER($A13)),AA13<0.000000000001),"",MAX(-1,MIN(1,Z13/AA13))) -> 0.55519108 | AC13: =IF(OR(NOT(ISNUMBER($A13)),AA13<0.000000000001),"",IF(Y13>=0,ACOS(MAX(-1,MIN(1,X13/AA13))),-ACOS(MAX(-1,MIN(1,X13/AA13))))) -> -1.4847445 | AD13: =IF(AB13="","",ACOS(AB13)) -> 0.98220364 | AE13: =IF(AC13="","",MOD(AC13+Geometry!$C$47*AD13+PI(),2*PI())-PI()) -> -0.50254082 | AF13: =IF(NOT(ISNUMBER($A13)),"",AND(AA13>=0.000000000001,ABS(Z13)<=AA13+0.00000001)) -> TRUE | AG13: =IF(AF13=FALSE,"",IF((Geometry!$C$28*COS(AE13)+Geometry!$C$32*SIN(AE13)+Geometry!$C$8*Geometry!$C$30*(1-COS(AE13)))>=0,1,-1)*ACOS(MAX(-1,MIN(1,(Geometry!$C$27*COS(AE13)+Geometry!$C$31*SIN(AE13)+Geometry!$C$7*Geometry!$C$30*(1-COS(AE13)))/SQRT((Geometry!$C$27*COS(AE13)+Geometry!$C$31*SIN(AE13)+Geometry!$C$7*Geometry!$C$30*(1-COS(AE13)))^2+(Geometry!$C$28*COS(AE13)+Geometry!$C$32*SIN(AE13)+Geometry!$C$8*Geometry!$C$30*(1-COS(AE13)))^2))))*180/PI()) -> -28.406335
A14: =IF(Inputs!$E$9+12*Inputs!$E$11<=Inputs!$E$10,Inputs!$E$9+12*Inputs!$E$11,"") -> -48 | B14: =IF(NOT(ISNUMBER($A14)),"",Inputs!$B$17+$A14*Inputs!$E$6/SQRT(Inputs!$E$6^2+Inputs!$E$7^2+Inputs!$E$8^2)) -> 919.873 | C14: =IF(NOT(ISNUMBER($A14)),"",Inputs!$C$17+$A14*Inputs!$E$7/SQRT(Inputs!$E$6^2+Inputs!$E$7^2+Inputs!$E$8^2)) -> 209.454 | D14: =IF(NOT(ISNUMBER($A14)),"",Inputs!$D$17+$A14*Inputs!$E$8/SQRT(Inputs!$E$6^2+Inputs!$E$7^2+Inputs!$E$8^2)) -> 182.189 | E14: =IF(NOT(ISNUMBER($A14)),"",Inputs!$B$15+Geometry!$B$15-B14) -> -24.932661 | F14: =IF(NOT(ISNUMBER($A14)),"",Inputs!$C$15+Geometry!$B$16-C14) -> 231.76798 | G14: =IF(NOT(ISNUMBER($A14)),"",Inputs!$D$15+Geometry!$B$17-D14) -> 11.015352 | H14: =IF(NOT(ISNUMBER($A14)),"",2*(E14*Geometry!$B$18+F14*Geometry!$B$19+G14*Geometry!$B$20)) -> 11024.969 | I14: =IF(NOT(ISNUMBER($A14)),"",2*(E14*Geometry!$B$21+F14*Geometry!$B$22+G14*Geometry!$B$23)) -> 68945.043 | J14: =IF(NOT(ISNUMBER($A14)),"",Geometry!$B$24^2-(E14^2+F14^2+G14^2)-(Geometry!$B$18^2+Geometry!$B$19^2+Geometry!$B$20^2)) -> -12619.543 | K14: =IF(NOT(ISNUMBER($A14)),"",SQRT(H14^2+I14^2)) -> 69820.977 | L14: =IF(OR(NOT(ISNUMBER($A14)),K14<0.000000000001),"",MAX(-1,MIN(1,J14/K14))) -> -0.18074142 | M14: =IF(OR(NOT(ISNUMBER($A14)),K14<0.000000000001),"",IF(I14>=0,ACOS(MAX(-1,MIN(1,H14/K14))),-ACOS(MAX(-1,MIN(1,H14/K14))))) -> 1.4122293 | N14: =IF(L14="","",ACOS(L14)) -> 1.7525366 | O14: =IF(M14="","",MOD(M14+Geometry!$B$47*N14+PI(),2*PI())-PI()) -> -0.34030728 | P14: =IF(NOT(ISNUMBER($A14)),"",AND(K14>=0.000000000001,ABS(J14)<=K14+0.00000001)) -> TRUE | Q14: =IF(P14=FALSE,"",IF((Geometry!$B$28*COS(O14)+Geometry!$B$32*SIN(O14)+Geometry!$B$8*Geometry!$B$30*(1-COS(O14)))>=0,1,-1)*ACOS(MAX(-1,MIN(1,(Geometry!$B$27*COS(O14)+Geometry!$B$31*SIN(O14)+Geometry!$B$7*Geometry!$B$30*(1-COS(O14)))/SQRT((Geometry!$B$27*COS(O14)+Geometry!$B$31*SIN(O14)+Geometry!$B$7*Geometry!$B$30*(1-COS(O14)))^2+(Geometry!$B$28*COS(O14)+Geometry!$B$32*SIN(O14)+Geometry!$B$8*Geometry!$B$30*(1-COS(O14)))^2))))*180/PI()) -> -19.120606 | R14: =IF(NOT(ISNUMBER($A14)),"",Inputs!$B$21+$A14*Inputs!$E$6/SQRT(Inputs!$E$6^2+Inputs!$E$7^2+Inputs!$E$8^2)) -> 919.873 | S14: =IF(NOT(ISNUMBER($A14)),"",Inputs!$C$21+$A14*Inputs!$E$7/SQRT(Inputs!$E$6^2+Inputs!$E$7^2+Inputs!$E$8^2)) -> -305.454 | T14: =IF(NOT(ISNUMBER($A14)),"",Inputs!$D$21+$A14*Inputs!$E$8/SQRT(Inputs!$E$6^2+Inputs!$E$7^2+Inputs!$E$8^2)) -> 182.189 | U14: =IF(NOT(ISNUMBER($A14)),"",Inputs!$B$19+Geometry!$C$15-R14) -> -24.932661 | V14: =IF(NOT(ISNUMBER($A14)),"",Inputs!$C$19+Geometry!$C$16-S14) -> -135.76798 | W14: =IF(NOT(ISNUMBER($A14)),"",Inputs!$D$19+Geometry!$C$17-T14) -> 11.015352 | X14: =IF(NOT(ISNUMBER($A14)),"",2*(U14*Geometry!$C$18+V14*Geometry!$C$19+W14*Geometry!$C$20)) -> 3627.3982 | Y14: =IF(NOT(ISNUMBER($A14)),"",2*(U14*Geometry!$C$21+V14*Geometry!$C$22+W14*Geometry!$C$23)) -> -41442.736 | Z14: =IF(NOT(ISNUMBER($A14)),"",Geometry!$C$24^2-(U14^2+V14^2+W14^2)-(Geometry!$C$18^2+Geometry!$C$19^2+Geometry!$C$20^2)) -> 22663.91 | AA14: =IF(NOT(ISNUMBER($A14)),"",SQRT(X14^2+Y14^2)) -> 41601.182 | AB14: =IF(OR(NOT(ISNUMBER($A14)),AA14<0.000000000001),"",MAX(-1,MIN(1,Z14/AA14))) -> 0.54479005 | AC14: =IF(OR(NOT(ISNUMBER($A14)),AA14<0.000000000001),"",IF(Y14>=0,ACOS(MAX(-1,MIN(1,X14/AA14))),-ACOS(MAX(-1,MIN(1,X14/AA14))))) -> -1.4834909 | AD14: =IF(AB14="","",ACOS(AB14)) -> 0.9946576 | AE14: =IF(AC14="","",MOD(AC14+Geometry!$C$47*AD14+PI(),2*PI())-PI()) -> -0.48883327 | AF14: =IF(NOT(ISNUMBER($A14)),"",AND(AA14>=0.000000000001,ABS(Z14)<=AA14+0.00000001)) -> TRUE | AG14: =IF(AF14=FALSE,"",IF((Geometry!$C$28*COS(AE14)+Geometry!$C$32*SIN(AE14)+Geometry!$C$8*Geometry!$C$30*(1-COS(AE14)))>=0,1,-1)*ACOS(MAX(-1,MIN(1,(Geometry!$C$27*COS(AE14)+Geometry!$C$31*SIN(AE14)+Geometry!$C$7*Geometry!$C$30*(1-COS(AE14)))/SQRT((Geometry!$C$27*COS(AE14)+Geometry!$C$31*SIN(AE14)+Geometry!$C$7*Geometry!$C$30*(1-COS(AE14)))^2+(Geometry!$C$28*COS(AE14)+Geometry!$C$32*SIN(AE14)+Geometry!$C$8*Geometry!$C$30*(1-COS(AE14)))^2))))*180/PI()) -> -27.626702
